Workbook

Sheet DCF
B3: DCF Model - Ryanair
B5: Ticker | D5: RYA.IR | F5: Implied Price Per Share | I5: =S81 -> 31.407939 | K5: Low-end
B6: Date | D6: ='Sources & Checks'!$B$4 -> 46087 | F6: Current Share Price | I6: ='Sources & Checks'!$B$5 -> 26.19 | K6: High-end
B7: Year end | D7: 46112 | F7: Implied Upside/Downside | I7: =I5/I6-1 -> 0.19923402
A9: X | B9: Assumption
B10: Switches | F10: Conservative | J10: Street/Base | N10: Optimistic
B11: Revenue | D11: 2 | F11: Revenue Growth (Norm.) | H11: 0.07 | J11: Revenue Growth (Norm.) | L11: ='Sources & Checks'!$B$19 -> 0.0909 | N11: Revenue Growth (Norm.) | P11: 0.11
B12: EBIT | D12: 2 | F12: Norm. Years: FY17-19, FY24-25 | H12: FY26 rate, fades to TGR by FY35 | J12: Norm. Years: FY17-19, FY24-25 | L12: FY26 rate, fades to TGR by FY35 | N12: Norm. Years: FY17-19, FY24-25 | P12: FY26 rate, fades to TGR by FY35
B13: WACC | D13: 2 | F13: EBIT Margin (Norm.) | H13: 0.16 | J13: EBIT Margin (Norm.) | L13: ='Sources & Checks'!$B$20 -> 0.1722 | N13: EBIT Margin (Norm.) | P13: 0.185
B14: TGR | D14: 2 | F14: D&A 8.0% | CapEx 18.3% | WC -2.9% | H14: Normalized avg | J14: D&A 8.0% | CapEx 18.3% | WC -2.9% | L14: Normalized avg | N14: D&A 8.0% | CapEx 18.3% | WC -2.9% | P14: Normalized avg
B16: WACC | D16: =CHOOSE(D13,H16,L16,P16) -> 0.085833824 | F16: WACC | H16: 0.092 | J16: WACC | L16: =WACC!F22 -> 0.085833824 | N16: WACC | P16: 0.082
B17: TGR | D17: =CHOOSE(D14,H17,L17,P17) -> 0.015 | F17: TGR | H17: 0.01 | J17: TGR | L17: 0.015 | N17: TGR | P17: 0.02
B18: Growth fade steps (FY27 to FY35) | D18: =COLUMNS(P40:X40) -> 9
A19: X | B19: Income Statement | E19: 2016 | F19: =E19+1 -> 2017 | G19: =F19+1 -> 2018 | H19: =G19+1 -> 2019 | I19: =H19+1 -> 2020 | J19: =I19+1 -> 2021 | K19: =J19+1 -> 2022 | L19: =K19+1 -> 2023 | M19: =L19+1 -> 2024 | ... X19: =W19+1 -> 2035
B20: Revenue | E20: 6535.8 | F20: 6647.8 | G20: 7151 | H20: 7697.4 | I20: 8494.8 | J20: 1635.8 | K20: 4800.9 | L20: 10775.2 | M20: 13443.8 | N20: 13948.5 | O20: =N20*(1+O21) -> 15216.419 | P20: =O20*(1+P21) -> 16471.266 | Q20: =P20*(1+Q21) -> 17690.689 | R20: =Q20*(1+R21) -> 18851.198 | S20: =R20*(1+S21) -> 19928.858 | T20: =T39 -> 20900.058 | U20: =U39 -> 21742.33 | V20: =V39 -> 22435.186 | W20: =W39 -> 22960.917 | X20: =X39 -> 23305.331
B21: % growth | F21: =F20/E20-1 -> 0.017136387 | G21: =G20/F20-1 -> 0.075694215 | H21: =H20/G20-1 -> 0.076408894 | I21: =I20/H20-1 -> 0.10359342 | J21: =J20/I20-1 -> -0.80743514 | K21: =K20/J20-1 -> 1.9348942 | L21: =L20/K20-1 -> 1.2444125 | M21: =M20/L20-1 -> 0.2476613 | N21: =N20/M20-1 -> 0.037541469 | O21: =O40 -> 0.0909 | P21: =P40 -> 0.082466667 | Q21: =Q40 -> 0.074033333 | R21: =R40 -> 0.0656 | S21: =S40 -> 0.057166667 | T21: =T40 -> 0.048733333 | U21: =U40 -> 0.0403 | V21: =V40 -> 0.031866667 | ... X21: =X40 -> 0.015
B22: EBITDA | E22: =E23+E28 -> 1887.4 | F22: =F23+F28 -> 2031.5 | G22: =G23+G28 -> 2228.3 | H22: =H23+H28 -> 1657.3 | I22: =I23+I28 -> 1876.1 | J22: =J23+J28 -> -268.4 | K22: =K23+K28 -> 379.8 | L22: =L23+L28 -> 2365.8 | ... N22: =N23+N28 -> 2772.4 | O22: =O45+O56 -> 3845.189 | P22: =P45+P56 -> 4162.2889 | Q22: =Q45+Q56 -> 4470.437 | R22: =R45+R56 -> 4763.6977 | S22: =S45+S56 -> 5036.0224 | T22: =T45+T56 -> 5281.4446 | U22: =U45+U56 -> 5494.2868 | V22: =V45+V56 -> 5669.3714 | ... X22: =X45+X56 -> 5889.257
B23: EBIT | E23: 1460.1 | F23: 1534 | G23: 1667.3 | H23: 1016.8 | I23: 1127.4 | J23: -839.4 | K23: -339.6 | L23: 1442.6 | M23: 2060.7 | N23: 1558 | O23: =O20*O24 -> 2620.2673 | P23: =P20*P24 -> 2836.352 | Q23: =Q20*Q24 -> 3046.3366 | R23: =R20*R24 -> 3246.1763 | S23: =S20*S24 -> 3431.7494 | T23: =T45 -> 3598.9899 | U23: =U45 -> 3744.0292 | V23: =V45 -> 3863.339 | W23: =W45 -> 3953.8699 | X23: =X45 -> 4013.1779
B24: % of Sales | E24: =E23/E20 -> 0.22340035 | F24: =F23/F20 -> 0.23075303 | G24: =G23/G20 -> 0.2331562 | H24: =H23/H20 -> 0.13209655 | I24: =I23/I20 -> 0.13271649 | J24: =J23/J20 -> -0.51314342 | K24: =K23/K20 -> -0.070736737 | L24: =L23/L20 -> 0.13388151 | ... N24: =N23/N20 -> 0.1116966 | O24: =O46 -> 0.1722 | P24: =P46 -> 0.1722 | Q24: =Q46 -> 0.1722 | R24: =R46 -> 0.1722 | S24: =S46 -> 0.1722 | T24: =T46 -> 0.1722 | U24: =U46 -> 0.1722 | V24: =V46 -> 0.1722 | ... X24: =X46 -> 0.1722
B25: Taxes | E25: 162.8 | F25: 154.4 | G25: 161.1 | H25: 63.1 | I25: 21.6 | J25: -93.6 | K25: -189 | L25: 128.7 | M25: 210.9 | N25: 172.8 | O25: =O23*O26 -> 262.02673 | P25: =P23*P26 -> 283.6352 | Q25: =Q23*Q26 -> 304.63366 | R25: =R23*R26 -> 324.61763 | S25: =S23*S26 -> 343.17494 | T25: =T51 -> 359.89899 | U25: =U51 -> 374.40292 | V25: =V51 -> 386.3339 | W25: =W51 -> 395.38699 | X25: =X51 -> 401.31779
B26: Tax rate | E26: =E25/E23 -> 0.11149921 | F26: =F25/F23 -> 0.10065189 | G26: =G25/G23 -> 0.096623283 | H26: =H25/H23 -> 0.062057435 | I26: =I25/I23 -> 0.019159127 | J26: =J25/J23 -> 0.11150822 | K26: =K25/K23 -> 0.5565371 | L26: =L25/L23 -> 0.089213919 | ... N26: =N25/N23 -> 0.11091142 | O26: =O52 -> 0.1 | P26: =P52 -> 0.1 | Q26: =Q52 -> 0.1 | R26: =R52 -> 0.1 | S26: =S52 -> 0.1 | T26: =T52 -> 0.1 | U26: =U52 -> 0.1 | V26: =V52 -> 0.1 | ... X26: =X52 -> 0.1
A27: X | B27: Cash Flow Items | E27: =E19 -> 2016 | F27: =F19 -> 2017 | G27: =G19 -> 2018 | H27: =H19 -> 2019 | I27: =I19 -> 2020 | J27: =J19 -> 2021 | K27: =K19 -> 2022 | L27: =L19 -> 2023 | ... S27: =S19 -> 2030 | T27: =T38 -> 2031 | U27: =U38 -> 2032 | V27: =V38 -> 2033 | W27: =W38 -> 2034 | X27: =X38 -> 2035
B28: D&A | E28: 427.3 | F28: 497.5 | G28: 561 | H28: 640.5 | I28: 748.7 | J28: 571 | K28: 719.4 | L28: 923.2 | M28: 1059.5 | N28: 1214.4 | O28: =O20*O29 -> 1224.9217 | P28: =P20*P29 -> 1325.9369 | Q28: =Q20*Q29 -> 1424.1004 | R28: =R20*R29 -> 1517.5214 | S28: =S20*S29 -> 1604.2731 | T28: =T56 -> 1682.4546 | U28: =U56 -> 1750.2576 | V28: =V56 -> 1806.0324 | W28: =W56 -> 1848.3538 | X28: =X56 -> 1876.0791
B29: % of Sales | E29: =E28/E20 -> 0.065378378 | F29: =F28/F20 -> 0.074836788 | G29: =G28/G20 -> 0.078450566 | H29: =H28/H20 -> 0.083209915 | I29: =I28/I20 -> 0.088136272 | J29: =J28/J20 -> 0.34906468 | K29: =K28/K20 -> 0.1498469 | L29: =L28/L20 -> 0.085678224 | ... N29: =N28/N20 -> 0.087063125 | O29: =O57 -> 0.0805 | P29: =P57 -> 0.0805 | Q29: =Q57 -> 0.0805 | R29: =R57 -> 0.0805 | S29: =S57 -> 0.0805 | T29: =T57 -> 0.0805 | U29: =U57 -> 0.0805 | V29: =V57 -> 0.0805 | ... X29: =X57 -> 0.0805
B31: CapEx | E31: 1217.7 | F31: 1449.8 | G31: 1470.6 | H31: 1546.7 | I31: 578.8 | J31: 294.7 | K31: 1181.6 | L31: 1914.7 | M31: 2391.9 | N31: 1552.5 | O31: =O20*O32 -> 2781.5613 | P31: =P20*P32 -> 3010.9474 | Q31: =Q20*Q32 -> 3233.8579 | R31: =R20*R32 -> 3445.999 | S31: =S20*S32 -> 3642.9952 | T31: =T59 -> 3820.5305 | U31: =U59 -> 3974.4979 | V31: =V59 -> 4101.1519 | W31: =W59 -> 4197.2556 | X31: =X59 -> 4260.2144
B32: % of Sales | E32: =E31/E20 -> 0.18631231 | F32: =F31/F20 -> 0.21808719 | G32: =G31/G20 -> 0.20564956 | H32: =H31/H20 -> 0.20093798 | I32: =I31/I20 -> 0.068135801 | J32: =J31/J20 -> 0.1801565 | K32: =K31/K20 -> 0.24612052 | L32: =L31/L20 -> 0.17769508 | ... N32: =N31/N20 -> 0.11130229 | O32: =O60 -> 0.1828 | P32: =P60 -> 0.1828 | Q32: =Q60 -> 0.1828 | R32: =R60 -> 0.1828 | S32: =S60 -> 0.1828 | T32: =T60 -> 0.1828 | U32: =U60 -> 0.1828 | V32: =V60 -> 0.1828 | ... X32: =X60 -> 0.1828
B34: Change in NW | E34: -135.6 | F34: -113.1 | G34: -168.9 | H34: -514.3 | I34: 388.5 | J34: 1703.2 | K34: -1785.9 | L34: -1353.9 | M34: -19 | N34: -480.3 | O34: =O20*O35 -> -436.71122 | P34: =P20*P35 -> -472.72533 | Q34: =Q20*Q35 -> -507.72277 | R34: =R20*R35 -> -541.02938 | S34: =S20*S35 -> -571.95823 | T34: =T62 -> -599.83166 | U34: =U62 -> -624.00487 | V34: =V62 -> -643.88983 | W34: =W62 -> -658.97831 | X34: =X62 -> -668.86299
B35: % of Sales | E35: =E34/E20 -> -0.020747269 | F35: =F34/F20 -> -0.017013147 | G35: =G34/G20 -> -0.023619074 | H35: =H34/H20 -> -0.066814769 | I35: =I34/I20 -> 0.045733861 | J35: =J34/J20 -> 1.0412031 | K35: =K34/K20 -> -0.37199275 | L35: =L34/L20 -> -0.12564964 | ... N35: =N34/N20 -> -0.03443381 | O35: =O63 -> -0.0287 | P35: =P63 -> -0.0287 | Q35: =Q63 -> -0.0287 | R35: =R63 -> -0.0287 | S35: =S63 -> -0.0287 | T35: =T63 -> -0.0287 | U35: =U63 -> -0.0287 | V35: =V63 -> -0.0287 | ... X35: =X63 -> -0.0287
B36: % of Change in Sales | F36: =F34/(F20-E20) -> -1.0098214 | G36: =G34/(G20-F20) -> -0.33565183 | H36: =H34/(H20-G20) -> -0.94125183 | I36: =I34/(I20-H20) -> 0.48720843 | J36: =J34/(J20-I20) -> -0.24831608 | K36: =K34/(K20-J20) -> -0.56424758 | L36: =L34/(L20-K20) -> -0.22662069 | M36: =M34/(M20-L20) -> -0.0071198381 | N36: =N34/(N20-M20) -> -0.95165445
A38: X | B38: DCF | E38: =E27 -> 2016 | F38: =E38+1 -> 2017 | G38: =F38+1 -> 2018 | H38: =G38+1 -> 2019 | I38: =H38+1 -> 2020 | J38: =I38+1 -> 2021 | K38: =J38+1 -> 2022 | L38: =K38+1 -> 2023 | M38: =L38+1 -> 2024 | ... X38: =W38+1 -> 2035 | Y38: TV year
B39: Revenue | E39: =E20 -> 6535.8 | F39: =F20 -> 6647.8 | G39: =G20 -> 7151 | H39: =H20 -> 7697.4 | I39: =I20 -> 8494.8 | J39: =J20 -> 1635.8 | K39: =K20 -> 4800.9 | L39: =L20 -> 10775.2 | ... N39: =N20 -> 13948.5 | O39: =N39*(1+O40) -> 15216.419 | P39: =O39*(1+P40) -> 16471.266 | Q39: =P39*(1+Q40) -> 17690.689 | R39: =Q39*(1+R40) -> 18851.198 | S39: =R39*(1+S40) -> 19928.858 | T39: =S39*(1+T40) -> 20900.058 | U39: =T39*(1+U40) -> 21742.33 | V39: =U39*(1+V40) -> 22435.186 | ... X39: =W39*(1+X40) -> 23305.331
B40: % growth | F40: =F39/E39-1 -> 0.017136387 | G40: =G39/F39-1 -> 0.075694215 | H40: =H39/G39-1 -> 0.076408894 | I40: =I39/H39-1 -> 0.10359342 | J40: =J39/I39-1 -> -0.80743514 | K40: =K39/J39-1 -> 1.9348942 | L40: =L39/K39-1 -> 1.2444125 | M40: =M39/L39-1 -> 0.2476613 | N40: =N39/M39-1 -> 0.037541469 | O40: =INDEX(O41:O43,$D$11) -> 0.0909 | P40: =INDEX(P41:P43,$D$11) -> 0.082466667 | Q40: =INDEX(Q41:Q43,$D$11) -> 0.074033333 | R40: =INDEX(R41:R43,$D$11) -> 0.0656 | S40: =INDEX(S41:S43,$D$11) -> 0.057166667 | T40: =INDEX(T41:T43,$D$11) -> 0.048733333 | U40: =INDEX(U41:U43,$D$11) -> 0.0403 | V40: =INDEX(V41:V43,$D$11) -> 0.031866667 | ... X40: =INDEX(X41:X43,$D$11) -> 0.015 | Y40: =$D$17 -> 0.015
B41: Conservative Case | O41: =$H$11 -> 0.07 | P41: =O41-($H$11-$H$17)/$D$18 -> 0.063333333 | Q41: =P41-($H$11-$H$17)/$D$18 -> 0.056666667 | R41: =Q41-($H$11-$H$17)/$D$18 -> 0.05 | S41: =R41-($H$11-$H$17)/$D$18 -> 0.043333333 | T41: =S41-($H$11-$H$17)/$D$18 -> 0.036666667 | U41: =T41-($H$11-$H$17)/$D$18 -> 0.03 | V41: =U41-($H$11-$H$17)/$D$18 -> 0.023333333 | W41: =V41-($H$11-$H$17)/$D$18 -> 0.016666667 | X41: =W41-($H$11-$H$17)/$D$18 -> 0.01
B42: Street Case | O42: =$L$11 -> 0.0909 | P42: =O42-($L$11-$L$17)/$D$18 -> 0.082466667 | Q42: =P42-($L$11-$L$17)/$D$18 -> 0.074033333 | R42: =Q42-($L$11-$L$17)/$D$18 -> 0.0656 | S42: =R42-($L$11-$L$17)/$D$18 -> 0.057166667 | T42: =S42-($L$11-$L$17)/$D$18 -> 0.048733333 | U42: =T42-($L$11-$L$17)/$D$18 -> 0.0403 | V42: =U42-($L$11-$L$17)/$D$18 -> 0.031866667 | W42: =V42-($L$11-$L$17)/$D$18 -> 0.023433333 | X42: =W42-($L$11-$L$17)/$D$18 -> 0.015
B43: Optimistic Case | O43: =$P$11 -> 0.11 | P43: =O43-($P$11-$P$17)/$D$18 -> 0.1 | Q43: =P43-($P$11-$P$17)/$D$18 -> 0.09 | R43: =Q43-($P$11-$P$17)/$D$18 -> 0.08 | S43: =R43-($P$11-$P$17)/$D$18 -> 0.07 | T43: =S43-($P$11-$P$17)/$D$18 -> 0.06 | U43: =T43-($P$11-$P$17)/$D$18 -> 0.05 | V43: =U43-($P$11-$P$17)/$D$18 -> 0.04 | W43: =V43-($P$11-$P$17)/$D$18 -> 0.03 | X43: =W43-($P$11-$P$17)/$D$18 -> 0.02
B45: EBIT | E45: =E23 -> 1460.1 | F45: =F23 -> 1534 | G45: =G23 -> 1667.3 | H45: =H23 -> 1016.8 | I45: =I23 -> 1127.4 | J45: =J23 -> -839.4 | K45: =K23 -> -339.6 | L45: =L23 -> 1442.6 | ... N45: =N23 -> 1558 | O45: =O39*O46 -> 2620.2673 | P45: =P39*P46 -> 2836.352 | Q45: =Q39*Q46 -> 3046.3366 | R45: =R39*R46 -> 3246.1763 | S45: =S39*S46 -> 3431.7494 | T45: =T39*T46 -> 3598.9899 | U45: =U39*U46 -> 3744.0292 | V45: =V39*V46 -> 3863.339 | ... X45: =X39*X46 -> 4013.1779
B46: % of Sales | E46: =E45/E20 -> 0.22340035 | F46: =F45/F20 -> 0.23075303 | G46: =G45/G20 -> 0.2331562 | H46: =H45/H20 -> 0.13209655 | I46: =I45/I20 -> 0.13271649 | J46: =J45/J20 -> -0.51314342 | K46: =K45/K20 -> -0.070736737 | L46: =L45/L20 -> 0.13388151 | ... N46: =N45/N20 -> 0.1116966 | O46: =INDEX(O47:O49,$D$12) -> 0.1722 | P46: =INDEX(P47:P49,$D$12) -> 0.1722 | Q46: =INDEX(Q47:Q49,$D$12) -> 0.1722 | R46: =INDEX(R47:R49,$D$12) -> 0.1722 | S46: =INDEX(S47:S49,$D$12) -> 0.1722 | T46: =INDEX(T47:T49,$D$12) -> 0.1722 | U46: =INDEX(U47:U49,$D$12) -> 0.1722 | V46: =INDEX(V47:V49,$D$12) -> 0.1722 | ... X46: =INDEX(X47:X49,$D$12) -> 0.1722
B47: Conservative Case | O47: =$H$13 -> 0.16 | P47: =$H$13 -> 0.16 | Q47: =$H$13 -> 0.16 | R47: =$H$13 -> 0.16 | S47: =$H$13 -> 0.16 | T47: =$H$13 -> 0.16 | U47: =$H$13 -> 0.16 | V47: =$H$13 -> 0.16 | ... X47: =$H$13 -> 0.16
B48: Street Case | O48: =$L$13 -> 0.1722 | P48: =$L$13 -> 0.1722 | Q48: =$L$13 -> 0.1722 | R48: =$L$13 -> 0.1722 | S48: =$L$13 -> 0.1722 | T48: =$L$13 -> 0.1722 | U48: =$L$13 -> 0.1722 | V48: =$L$13 -> 0.1722 | ... X48: =$L$13 -> 0.1722
B49: Optimistic Case | O49: =$P$13 -> 0.185 | P49: =$P$13 -> 0.185 | Q49: =$P$13 -> 0.185 | R49: =$P$13 -> 0.185 | S49: =$P$13 -> 0.185 | T49: =$P$13 -> 0.185 | U49: =$P$13 -> 0.185 | V49: =$P$13 -> 0.185 | ... X49: =$P$13 -> 0.185
...

Sheet Changes
B1: Changes in v2
B2: Green cells = new or changed in v2
B4: 1. Changes made
B5: Change | C5: Cells | D5: Explanation
B6: 1. Blume adjusted beta | C6: WACC!F14, F10 | D6: Adjusted beta = 1/3 x 1 + 2/3 x raw beta, used in the cost of equity
B7: 2. Terminal FCF tied to growth | C7: DCF!Y54:Y66, X73 | D7: Terminal FCF = NOPAT FY35 x (1+g) x (1 - g/WACC), TV = FCF / (WACC - g)
B8: 3. Growth fades to terminal rate | C8: DCF!P41:X43, D18 | D8: From FY27 growth falls by (start growth - TGR) / 9 a year, FY35 growth = TGR
B10: 2. Before and after (base case)
C11: Before | D11: After | E11: Change
B12: Beta used in cost of equity | C12: =WACC!$F$12 -> 1.01 | D12: =WACC!$F$14 -> 1.0066667 | E12: =D12-C12 -> -0.0033333333
B13: Cost of equity | C13: =Calc!$C$13 -> 0.089243 | D13: =WACC!$F$10 -> 0.089043 | E13: =D13-C13 -> -0.0002
B14: WACC | C14: =Calc!$C$14 -> 0.086023479 | D14: =WACC!$F$22 -> 0.085833824 | E14: =D14-C14 -> -0.00018965499
B15: Revenue growth FY26 | C15: =Calc!$F$21 -> 0.0909 | D15: =DCF!$O$40 -> 0.0909 | E15: =D15-C15 -> 0
B16: Revenue growth FY35 | C16: =Calc!$O$21 -> 0.0909 | D16: =DCF!$X$40 -> 0.015 | E16: =D16-C16 -> -0.0759
B17: NOPAT FY35 | C17: =Calc!$O$23 -> 5160.0342 | D17: =DCF!$X$54 -> 3611.8601 | E17: =D17-C17 -> -1548.1741
B18: Unlevered FCF FY35 | C18: =Calc!$O$27 -> 2709.534 | D18: =DCF!$X$66 -> 1896.5878 | E18: =D18-C18 -> -812.94623
B19: Terminal-year FCF | C19: =Calc!$P$27 -> 2750.177 | D19: =DCF!$Y$66 -> 3025.3749 | E19: =D19-C19 -> 275.19781
B20: Terminal reinvestment (% of NOPAT) | C20: =Calc!$C$34 -> 0.47489999 | D20: =DCF!$Y$64 -> 0.17475628 | E20: =D20-C20 -> -0.3001437
B21: Terminal value | C21: =Calc!$C$29 -> 38722.083 | D21: =DCF!$X$73 -> 42710.879 | E21: =D21-C21 -> 3988.7956
B22: PV of terminal value | C22: =Calc!$C$30 -> 19091.346 | D22: =DCF!$X$74 -> 21089.502 | E22: =D22-C22 -> 1998.1559
B23: Sum of PV of FCF FY26 to FY35 | C23: =Calc!$C$28 -> 13045.074 | D23: =SUM(DCF!$O$67:$X$67) -> 11516.487 | E23: =D23-C23 -> -1528.5868
B24: Enterprise value | C24: =Calc!$C$31 -> 32136.42 | D24: =DCF!$S$75 -> 32605.989 | E24: =D24-C24 -> 469.56915
B25: Equity value | C25: =Calc!$C$32 -> 33036.42 | D25: =DCF!$S$78 -> 33505.989 | E25: =D25-C25 -> 469.56915
B26: Implied price per share (EUR) | C26: =Calc!$C$33 -> 30.967773 | D26: =DCF!$S$81 -> 31.407939 | E26: =D26-C26 -> 0.44016606
B27: Upside against current price | C27: =C26/'Sources & Checks'!$B$5-1 -> 0.18242737 | D27: =DCF!$I$7 -> 0.19923402 | E27: =D27-C27 -> 0.016806646
B28: Conservative scenario price (EUR) | C28: =Calc!$C$186 -> 20.643856 | D28: =DCF!$L$87 -> 23.673836 | E28: =D28-C28 -> 3.0299799
B29: Optimistic scenario price (EUR) | C29: =Calc!$C$205 -> 45.362809 | D29: =DCF!$L$89 -> 40.042186 | E29: =D29-C29 -> -5.3206226
B31: 3. Checkpoint reconciliation (EUR per share)
B32: Step | C32: Model | D32: Reference | E32: Difference | F32: Status
B33: Original model | C33: =Calc!$C$33 -> 30.967773 | D33: 30.97 | E33: =C33-D33 -> -0.0022271251 | F33: =IF(ABS(E33)<=$C$38,"OK","CHECK") -> OK
B34: Change 1 only | C34: =Calc!$C$52 -> 31.051468 | D34: 31.1 | E34: =C34-D34 -> -0.048531644 | F34: =IF(ABS(E34)<=$C$38,"OK","CHECK") -> OK
B35: Change 2 only, growth flat | C35: =Calc!$C$71 -> 41.210082 | D35: 41.2 | E35: =C35-D35 -> 0.010082151 | F35: =IF(ABS(E35)<=$C$38,"OK","CHECK") -> OK
B36: Changes 1 and 2, growth flat | C36: =Calc!$C$90 -> 41.323397 | D36: 41.4 | E36: =C36-D36 -> -0.076603105 | F36: =IF(ABS(E36)<=$C$38,"OK","CHECK") -> OK
B37: All three changes | C37: =Calc!$C$109 -> 31.407939 | D37: 31.4 | E37: =C37-D37 -> 0.0079389359 | F37: =IF(ABS(E37)<=$C$38,"OK","CHECK") -> OK
B38: Tolerance | C38: 0.3
B40: 4. Known weak points
B41: Tax at 10% against Pillar Two. 15% would give about 28 per share on the original model and about 29 on v2.
B42: FY26 FCF is not prorated for the stub period.
B43: The "Total Debt 10,470" label in the Ratios balance sheet table is actually total liabilities.
B44: Leases are not added to debt separately.

Sheet Valuation
B2: Comps
N4: Financial Data | T4: Multiples | Y4: Multiples (EBIT basis)
H5: Price | J5: Market Cap | L5: EV | N5: Growth 24 | O5: Growth 25 | Q5: EBIT Margin 24 | R5: EBIT Margin 25 | T5: EV/EBITDA 24 | U5: EV/EBITDA 25 | W5: EV/Sales 24 | X5: EV/Sales 25 | Y5: EV/EBIT 24 | Z5: EV/EBIT 25
B6: Ticker | D6: Name | H6: (Local CCY) | J6: (Local CCY M) | L6: (Local CCY M) | N6: (%) | O6: (%) | Q6: (%) | R6: (%) | T6: (x) | U6: (x) | V6: (x) | W6: (x) | X6: (x) | Y6: (x) | Z6: (x)
H7: EUR / GBP | J7: EUR M / GBP M | L7: EUR M / GBP M
B8: RYA.IR | D8: Ryanair Holdings plc | H8: ='Sources & Checks'!$B$5 -> 26.19 | J8: ='Sources & Checks'!$B$8*H8 -> 27499.5 | L8: =J8-'Sources & Checks'!$B$6+'Sources & Checks'!$B$7 -> 26599.5 | N8: =DCF!M21 -> 0.2476613 | O8: =DCF!N21 -> 0.037541469 | Q8: =DCF!M24 -> 0.15328255 | R8: =DCF!N24 -> 0.1116966 | T8: =L8/DCF!M22 -> 8.5249343 | U8: =L8/DCF!N22 -> 9.5943947 | W8: =L8/DCF!M20 -> 1.97857 | X8: =L8/DCF!N20 -> 1.9069792 | Y8: =L8/DCF!M23 -> 12.907992 | Z8: =L8/DCF!N23 -> 17.07285
B10: EZJ.L | D10: easyJet plc | H10: 4.089 | J10: 3287.49 | L10: 2450 | N10: 0.1393 | O10: 0.0856 | Q10: 0.064131486 | R10: 0.069562636 | T10: 1.7922458 | U10: 1.6943292 | W10: 0.26318616 | X10: 0.24243024 | Y10: 4.1039 | Z10: 3.485
B11: WIZZ.L | D11: Wizz Air Holdings plc | H11: 9.275 | J11: 1166.6 | L11: 5950.1 | N11: 0.3 | O11: 0.0454 | Q11: 0.086370809 | R11: 0.031603774 | T11: 4.9866745 | U11: 5.245614 | W11: 1.1735897 | X11: 1.1226604 | Y11: 13.5878 | Z11: 35.5227
B12: IAG.MC | D12: International Airlines Group | H12: 4.464 | J12: 19080 | L12: 25060 | N12: 0.089871999 | O12: 0.034672897 | Q12: 0.13841121 | R12: 0.15126607 | T12: 3.6815043 | U12: 3.2978023 | W12: 0.78068536 | X12: 0.75452383 | Y12: 5.6403 | Z12: 4.9881
B13: LHA.DE | D13: Deutsche Lufthansa AG | H13: 8.12 | J13: 9740 | L13: 17780 | N13: 0.060352125 | O13: 0.053644129 | Q13: 0.043772119 | R13: 0.049498699 | T13: 4.4650929 | U13: 4.1071841 | W13: 0.47311141 | X13: 0.44902392 | Y13: 10.8085 | Z13: 9.0714
B14: AF.PA | D14: Air France-KLM | H14: 10.09 | J14: 2650 | L14: 3020 | N14: 0.047969619 | O14: 0.049206904 | Q14: 0.051 | R14: 0.061 | T14: 0.71159284 | U14: 0.59707394 | W14: 0.095997966 | X14: 0.091495743 | Y14: 1.8822 | Z14: 1.5
B20: PEER AVG (EX-RYA) | N20: =IF(COUNT(N10:N17)=0,"",AVERAGE(N10:N17)) -> 0.12749875 | O20: =IF(COUNT(O10:O17)=0,"",AVERAGE(O10:O17)) -> 0.053704786 | P20: =IF(COUNT(P8:P17)=0,"",AVERAGE(P8:P17)) | Q20: =IF(COUNT(Q10:Q17)=0,"",AVERAGE(Q10:Q17)) -> 0.076737126 | R20: =IF(COUNT(R10:R17)=0,"",AVERAGE(R10:R17)) -> 0.072586236 | S20: =IF(COUNT(S8:S17)=0,"",AVERAGE(S8:S17)) | T20: =IF(COUNT(T10:T17)=0,"",AVERAGE(T10:T17)) -> 3.1274221 | U20: =IF(COUNT(U10:U17)=0,"",AVERAGE(U10:U17)) -> 2.9884007 | V20: =IF(COUNT(V8:V17)=0,"",AVERAGE(V8:V17)) | W20: =IF(COUNT(W10:W17)=0,"",AVERAGE(W10:W17)) -> 0.55731413 | X20: =IF(COUNT(X10:X17)=0,"",AVERAGE(X10:X17)) -> 0.53202682 | Y20: =IF(COUNT(Y10:Y17)=0,"",AVERAGE(Y10:Y17)) -> 7.20454 | Z20: =IF(COUNT(Z10:Z17)=0,"",AVERAGE(Z10:Z17)) -> 10.91344
B21: PEER MEDIAN (EX-RYA) | N21: =IF(COUNT(N10:N17)=0,"",MEDIAN(N10:N17)) -> 0.089871999 | O21: =IF(COUNT(O10:O17)=0,"",MEDIAN(O10:O17)) -> 0.049206904 | P21: =IF(COUNT(P8:P17)=0,"",MEDIAN(P8:P17)) | Q21: =IF(COUNT(Q10:Q17)=0,"",MEDIAN(Q10:Q17)) -> 0.064131486 | R21: =IF(COUNT(R10:R17)=0,"",MEDIAN(R10:R17)) -> 0.061 | S21: =IF(COUNT(S8:S17)=0,"",MEDIAN(S8:S17)) | T21: =IF(COUNT(T10:T17)=0,"",MEDIAN(T10:T17)) -> 3.6815043 | U21: =IF(COUNT(U10:U17)=0,"",MEDIAN(U10:U17)) -> 3.2978023 | V21: =IF(COUNT(V8:V17)=0,"",MEDIAN(V8:V17)) | W21: =IF(COUNT(W10:W17)=0,"",MEDIAN(W10:W17)) -> 0.47311141 | X21: =IF(COUNT(X10:X17)=0,"",MEDIAN(X10:X17)) -> 0.44902392 | Y21: =IF(COUNT(Y10:Y17)=0,"",MEDIAN(Y10:Y17)) -> 5.6403 | Z21: =IF(COUNT(Z10:Z17)=0,"",MEDIAN(Z10:Z17)) -> 4.9881
B24: Implied Valuation from Peer Medians (Ryanair)
B25: Metric | C25: Peer Median Multiple (FY25) | D25: Ryanair Metric (FY25, EUR M) | E25: Implied EV (EUR M) | F25: (+) Cash | G25: (-) Debt | H25: Implied Equity (EUR M) | I25: Implied Price (€) | J25: vs. Mkt €26.19
B26: EV/EBITDA (FY25) | C26: =U21 -> 3.2978023 | D26: =DCF!N22 -> 2772.4 | E26: =C26*D26 -> 9142.8272 | F26: ='Sources & Checks'!$B$6 -> 2400 | G26: ='Sources & Checks'!$B$7 -> 1500 | H26: =E26+F26-G26 -> 10042.827 | I26: =H26/'Sources & Checks'!$B$9 -> 9.4139738 | J26: =I26/'Sources & Checks'!$B$5-1 -> -0.64055083
B27: EV/Sales (FY25) | C27: =X21 -> 0.44902392 | D27: =DCF!N20 -> 13948.5 | E27: =C27*D27 -> 6263.2101 | F27: ='Sources & Checks'!$B$6 -> 2400 | G27: ='Sources & Checks'!$B$7 -> 1500 | H27: =E27+F27-G27 -> 7163.2101 | I27: =H27/'Sources & Checks'!$B$9 -> 6.7146701 | J27: =I27/'Sources & Checks'!$B$5-1 -> -0.74361702
B28: EV/EBIT (FY25) | C28: =Z21 -> 4.9881 | D28: =DCF!N23 -> 1558 | E28: =C28*D28 -> 7771.4598 | F28: ='Sources & Checks'!$B$6 -> 2400 | G28: ='Sources & Checks'!$B$7 -> 1500 | H28: =E28+F28-G28 -> 8671.4598 | I28: =H28/'Sources & Checks'!$B$9 -> 8.1284775 | J28: =I28/'Sources & Checks'!$B$5-1 -> -0.68963431
B30: Note: Peer medians exclude Ryanair (EX-RYA). Implied EV = Multiple × Ryanair metric. Net Debt Bridge: (+) Cash €2,400M, (−) Debt €1,500M. Shares: 1,066.8M diluted. Large discount vs DCF reflects Ryanair's structurally superior margins vs legacy carriers — direct comps multiples understate intrinsic value.

Sheet WACC
B2: WACC
B4: WACC = % of equity x cost of equity + % of debt x cost of debt x (1- Tax Rate)
B5: Cost of equity = Risk Free rate + Adjusted Beta x Market Risk Premium
A7: X | B7: WACC
B8: Market Cap | F8: ='Sources & Checks'!$B$8*'Sources & Checks'!$B$5 -> 27499.5
B9: % of Equity | F9: =F8/(F8+F15) -> 0.94827497
B10: Cost of Equity | F10: =F11+F14*F13 -> 0.089043
B11: Risk Free Rate | F11: ='Sources & Checks'!$B$10 -> 0.028643
B12: Beta (raw) | F12: ='Sources & Checks'!$B$11 -> 1.01
B13: Market Risk Premium | F13: ='Sources & Checks'!$B$12 -> 0.06
B14: Adjusted Beta (Blume: 1/3 x 1.0 + 2/3 x raw beta) | F14: =1/3*1+2/3*F12 -> 1.0066667
A15: X | B15: Debt | F15: ='Sources & Checks'!$B$7 -> 1500
B16: % of Debt | F16: =F15/(F15+F8) -> 0.05172503
B17: Cost of Debt | F17: ='Sources & Checks'!$B$13 -> 0.03
B18: Tax Rate | F18: ='Sources & Checks'!$B$14 -> 0.1
A20: X | B20: Total | F20: =F15+F8 -> 28999.5
A22: X | B22: WACC | F22: =F9*F10+(F16*F17*(1-F18)) -> 0.085833824

Sheet Sources & Checks
A1: Verified Inputs & Sources
A3: Metric | B3: Value | C3: Units | D3: Source / Note
A4: Valuation date | B4: 46087 | C4: date | D4: Aligned to market price date used in the model.
A5: Current share price | B5: 26.19 | C5: EUR/share | D5: Euronext Dublin last traded price on 06/03/2026.
A6: Gross cash | B6: 2400 | C6: EUR m | D6: Ryanair Q3 FY26 results: gross cash at 31 Dec 2025.
A7: Gross debt | B7: 1500 | C7: EUR m | D7: Ryanair Q3 FY26 results: gross debt at 31 Dec 2025.
A8: Basic shares outstanding | B8: 1050 | C8: m shares | D8: Balance at 31 Dec 2025; used for market cap and EV bridge.
A9: Diluted shares | B9: 1066.8 | C9: m shares | D9: 9M FY26 diluted weighted average shares; used for per-share DCF.
A10: Risk-free rate | B10: 0.028643 | C10: % | D10: Germany 10Y government bond yield on 06/03/2026.
A11: Beta | B11: 1.01 | C11: x | D11: Analyst assumption retained from original model.
A12: Market risk premium | B12: 0.06 | C12: % | D12: Analyst assumption retained from original model.
A13: Pre-tax cost of debt | B13: 0.03 | C13: % | D13: Analyst assumption retained from original model.
A14: Tax rate | B14: 0.1 | C14: % | D14: Analyst assumption retained from original model / Irish tax profile.
A16: Control note | B16: Market cap uses basic shares; DCF per-share output uses diluted shares.
A18: DCF Forecast Methodology | B18: Normalized Historical Average | C18: - | D18: All forecast drivers (revenue growth, EBIT margin, D&A, CapEx, ΔWC) use flat normalized avg. Normal years: FY2017-2019 + FY2024-2025. Excluded: FY2020-2023 (Covid disruption + rebound distortion). Revenue growth starts at the normalised rate in FY26 and fades in equal steps to the terminal growth rate by FY35.
A19: Normalized Revenue Growth | B19: 0.0909 | C19: % | D19: Avg of FY17(1.7%), FY18(7.6%), FY19(7.6%), FY24(24.8%), FY25(3.8%) excl. Covid years
A20: Normalized EBIT Margin | B20: 0.1722 | C20: % | D20: Avg of FY17(23.1%), FY18(23.3%), FY19(13.2%), FY24(15.3%), FY25(11.2%) excl. Covid years
A21: Normalized D&A % | B21: 0.0805 | C21: % | D21: Avg of FY17-FY19 + FY24-FY25 D&A as % of Revenue
A22: Normalized CapEx % | B22: 0.1828 | C22: % | D22: Avg of FY17-FY19 + FY24-FY25 CapEx as % of Revenue
A23: Normalized ΔWC % | B23: -0.0287 | C23: % | D23: Avg of FY17-FY19 + FY24-FY25 change in net working capital as % of Revenue (negative = cash source, typical for airlines)
A25: ⚠ Data Note | B25: FY2016 historical revenue (€6,535.8M) should be verified against Ryanair's FY2016 Annual Report (year ended 31 March 2016). Some databases report FY2016 total revenues as ~€5,654M (ex-ancillary supplements). If restated, the normalized growth average would adjust from 9.09% to approx. 9.5%.

Sheet Ratios
B3: Income Statement Data (€ million) | C3: FY23 | D3: FY24 | E3: FY25
B4: Total Revenue1 | C4: 10775 | D4: 13444 | E4: 13949
B5: Total Operating Costs1 | C5: 9332 | D5: 11383 | E5: 12391
B6: Profit Before Tax1 | C6: 1443 | D6: 2128 | E6: 1785
B7: Profit After Tax (Net Income)1 | C7: 1314 | D7: 1917 | E7: 1612
B10: Balance Sheet Data (€ million) | C10: FY23 | D10: FY24 | E10: FY25
B11: Total Assets1 | C11: 16406 | D11: 17176 | E11: 17507
B12: Shareholder Equity1 | C12: 5643 | D12: 7614 | E12: 7037
B13: Gross Cash1 | C13: 4675 | D13: 4120 | E13: 3987
B16: Debt | C16: FY23 | D16: FY24 | E16: FY25
B17: Current Liabilities1 | C17: 7422 | D17: 6401 | E17: 8153
B18: Non-Current Liabilities1 | C18: 3341 | D18: 3161 | E18: 2317
B19: Total Debt | C19: =C17+C18 -> 10763 | D19: =D17+D18 -> 9562 | E19: =E17+E18 -> 10470
B22: Ratio | C22: FY23 | D22: FY24 | E22: FY25
B23: Revenue Growth | C23: =(C4-4800.9)/4800.9 -> 1.2443708 | D23: =(D4-C4)/C4 -> 0.24770302 | E23: =(E4-D4)/D4 -> 0.037563225
B24: Net Income Growth | C24: n.m | D24: =(D7-C7)/C7 -> 0.45890411 | E24: =(E7-D7)/D7 -> -0.15910276
B25: Net Profit Margin | C25: =C7/C4 -> 0.12194896 | D25: =D7/D4 -> 0.14259149 | E25: =E7/E4 -> 0.11556384
B26: Operating Margin | C26: =(C4-C5)/C4 -> 0.13392111 | D26: =(D4-D5)/D4 -> 0.15330259 | E26: =(E4-E5)/E4 -> 0.11169259
B27: Cost-to-Revenue | C27: =C5/C4 -> 0.86607889 | D27: =D5/D4 -> 0.84669741 | E27: =E5/E4 -> 0.88830741
B28: ROA | C28: =C7/C11 -> 0.080092649 | D28: =D7/D11 -> 0.11160922 | E28: =E7/E11 -> 0.092077455
B29: ROE | C29: =C7/C12 -> 0.23285486 | D29: =D7/D12 -> 0.25177305 | E29: =E7/E12 -> 0.22907489
B30: Debt Ratio | C30: =C19/C11 -> 0.65604047 | D30: =D19/D11 -> 0.55670703 | E30: =E19/E11 -> 0.5980465
B31: Equity Ratio | C31: =C12/C11 -> 0.34395953 | D31: =D12/D11 -> 0.44329297 | E31: =E12/E11 -> 0.4019535
B33: 1 Ryanair Holdings plc. (2025). Ryanair 2025 annual report. Retrieved 6 March 2026
B35: Note: Revenue Growth (FY23) - Calculated using FY22 revenue of €4,800.9m and FY23 revenue of €10,775m, resulting in growth of 124.40%. FY22 is used only as a base year.
B36: Note: Net Income Growth (FY23) - FY22 net income was a loss of €240.8m, while FY23 net income was €1,313.8m. Because the base year is negative, the growth rate is not meaningful and reflects a turnaround from loss to profit.

Sheet Calc
B1: Calc
B3: Inputs
B4: Tax rate | C4: ='Sources & Checks'!$B$14 -> 0.1
B5: D&A (% of sales) | C5: ='Sources & Checks'!$B$21 -> 0.0805
B6: CapEx (% of sales) | C6: ='Sources & Checks'!$B$22 -> 0.1828
B7: Change in NWC (% of sales, negative = cash source) | C7: ='Sources & Checks'!$B$23 -> -0.0287
B8: Revenue FY25 (base year, EUR m) | C8: =DCF!$N$20 -> 13948.5
B9: Cash (EUR m) | C9: ='Sources & Checks'!$B$6 -> 2400
B10: Debt (EUR m) | C10: ='Sources & Checks'!$B$7 -> 1500
B11: Diluted shares (m) | C11: ='Sources & Checks'!$B$9 -> 1066.8
B12: Growth fade steps (FY27 to FY35) | C12: =DCF!$D$18 -> 9
B13: Cost of equity with raw beta | C13: =WACC!$F$11+WACC!$F$12*WACC!$F$13 -> 0.089243
B14: WACC with raw beta (before Change 1) | C14: =WACC!$F$9*C13+WACC!$F$16*WACC!$F$17*(1-WACC!$F$18) -> 0.086023479
B15: WACC with Blume adjusted beta (after Change 1) | C15: =WACC!$F$22 -> 0.085833824
B18: Checkpoint steps
B19: Step 0. Original model
B20: Parameter | C20: Value | E20: Line | F20: ="FY"&RIGHT(DCF!O$38,2) -> FY26 | G20: ="FY"&RIGHT(DCF!P$38,2) -> FY27 | H20: ="FY"&RIGHT(DCF!Q$38,2) -> FY28 | I20: ="FY"&RIGHT(DCF!R$38,2) -> FY29 | J20: ="FY"&RIGHT(DCF!S$38,2) -> FY30 | K20: ="FY"&RIGHT(DCF!T$38,2) -> FY31 | L20: ="FY"&RIGHT(DCF!U$38,2) -> FY32 | M20: ="FY"&RIGHT(DCF!V$38,2) -> FY33 | ... O20: ="FY"&RIGHT(DCF!X$38,2) -> FY35 | P20: TV year
B21: Start growth (FY26) | C21: =DCF!$L$11 -> 0.0909 | E21: Revenue growth | F21: =$C$21 -> 0.0909 | G21: =IF($C$25=1,F21-($C$21-$C$24)/$C$12,$C$21) -> 0.0909 | H21: =IF($C$25=1,G21-($C$21-$C$24)/$C$12,$C$21) -> 0.0909 | I21: =IF($C$25=1,H21-($C$21-$C$24)/$C$12,$C$21) -> 0.0909 | J21: =IF($C$25=1,I21-($C$21-$C$24)/$C$12,$C$21) -> 0.0909 | K21: =IF($C$25=1,J21-($C$21-$C$24)/$C$12,$C$21) -> 0.0909 | L21: =IF($C$25=1,K21-($C$21-$C$24)/$C$12,$C$21) -> 0.0909 | M21: =IF($C$25=1,L21-($C$21-$C$24)/$C$12,$C$21) -> 0.0909 | N21: =IF($C$25=1,M21-($C$21-$C$24)/$C$12,$C$21) -> 0.0909 | O21: =IF($C$25=1,N21-($C$21-$C$24)/$C$12,$C$21) -> 0.0909
B22: EBIT margin | C22: =DCF!$L$13 -> 0.1722 | E22: Revenue | F22: =$C$8*(1+F21) -> 15216.419 | G22: =F22*(1+G21) -> 16599.591 | H22: =G22*(1+H21) -> 18108.494 | I22: =H22*(1+I21) -> 19754.556 | J22: =I22*(1+J21) -> 21550.245 | K22: =J22*(1+K21) -> 23509.162 | L22: =K22*(1+L21) -> 25646.145 | M22: =L22*(1+M21) -> 27977.38 | N22: =M22*(1+N21) -> 30520.524 | O22: =N22*(1+O21) -> 33294.839
B23: WACC | C23: =$C$14 -> 0.086023479 | E23: NOPAT = EBIT x (1 - tax) | F23: =F22*$C$22*(1-$C$4) -> 2358.2406 | G23: =G22*$C$22*(1-$C$4) -> 2572.6046 | H23: =H22*$C$22*(1-$C$4) -> 2806.4544 | I23: =I22*$C$22*(1-$C$4) -> 3061.5611 | J23: =J22*$C$22*(1-$C$4) -> 3339.857 | K23: =K22*$C$22*(1-$C$4) -> 3643.45 | L23: =L22*$C$22*(1-$C$4) -> 3974.6396 | M23: =M22*$C$22*(1-$C$4) -> 4335.9343 | ... O23: =O22*$C$22*(1-$C$4) -> 5160.0342 | P23: =O23*(1+$C$24) -> 5237.4347
B24: Terminal growth rate | C24: =DCF!$L$17 -> 0.015 | E24: D&A | F24: =F22*$C$5 -> 1224.9217 | G24: =G22*$C$5 -> 1336.2671 | H24: =H22*$C$5 -> 1457.7338 | I24: =I22*$C$5 -> 1590.2418 | J24: =J22*$C$5 -> 1734.7947 | K24: =K22*$C$5 -> 1892.4876 | L24: =L22*$C$5 -> 2064.5147 | M24: =M22*$C$5 -> 2252.1791 | ... O24: =O22*$C$5 -> 2680.2346
B25: Growth fade (1 = yes, 0 = flat) | C25: 0 | E25: CapEx | F25: =F22*$C$6 -> 2781.5613 | G25: =G22*$C$6 -> 3034.4053 | H25: =H22*$C$6 -> 3310.2327 | I25: =I22*$C$6 -> 3611.1328 | J25: =J22*$C$6 -> 3939.3848 | K25: =K22*$C$6 -> 4297.4749 | L25: =L22*$C$6 -> 4688.1154 | M25: =M22*$C$6 -> 5114.2651 | ... O25: =O22*$C$6 -> 6086.2966
B26: Terminal FCF with g/WACC reinvestment (1 = yes, 0 = old) | C26: 0 | E26: Change in NWC | F26: =F22*$C$7 -> -436.71122 | G26: =G22*$C$7 -> -476.40826 | H26: =H22*$C$7 -> -519.71378 | I26: =I22*$C$7 -> -566.95576 | J26: =J22*$C$7 -> -618.49204 | K26: =K22*$C$7 -> -674.71296 | L26: =L22*$C$7 -> -736.04437 | M26: =M22*$C$7 -> -802.9508 | ... O26: =O22*$C$7 -> -955.56189
E27: Unlevered FCF | F27: =F23+F24-F25-F26 -> 1238.3121 | G27: =G23+G24-G25-G26 -> 1350.8747 | H27: =H23+H24-H25-H26 -> 1473.6692 | I27: =I23+I24-I25-I26 -> 1607.6258 | J27: =J23+J24-J25-J26 -> 1753.759 | K27: =K23+K24-K25-K26 -> 1913.1756 | L27: =L23+L24-L25-L26 -> 2087.0833 | M27: =M23+M24-M25-M26 -> 2276.7992 | ... O27: =O23+O24-O25-O26 -> 2709.534 | P27: =IF($C$26=1,P23*(1-$C$24/$C$23),O27*(1+$C$24)) -> 2750.177
B28: Sum of PV of FCF FY26 to FY35 | C28: =SUM(F29:O29) -> 13045.074 | E28: Discount period (years) | F28: =DCF!O$71 -> 0.034722222 | G28: =DCF!P$71 -> 0.56944444 | H28: =DCF!Q$71 -> 1.5694444 | I28: =DCF!R$71 -> 2.5694444 | J28: =DCF!S$71 -> 3.5694444 | K28: =DCF!T$71 -> 4.5694444 | L28: =DCF!U$71 -> 5.5694444 | M28: =DCF!V$71 -> 6.5694444 | ... O28: =DCF!X$71 -> 8.5694444
B29: Terminal value | C29: =P27/($C$23-$C$24) -> 38722.083 | E29: PV of FCF | F29: =F27/(1+$C$23)^F28 -> 1234.769 | G29: =G27/(1+$C$23)^G28 -> 1288.8626 | H29: =H27/(1+$C$23)^H28 -> 1294.65 | I29: =I27/(1+$C$23)^I28 -> 1300.4633 | J29: =J27/(1+$C$23)^J28 -> 1306.3027 | K29: =K27/(1+$C$23)^K28 -> 1312.1683 | L29: =L27/(1+$C$23)^L28 -> 1318.0603 | M29: =M27/(1+$C$23)^M28 -> 1323.9787 | ... O29: =O27/(1+$C$23)^O28 -> 1335.8954
B30: PV of terminal value | C30: =C29/(1+$C$23)^O28 -> 19091.346
B31: Enterprise value | C31: =C28+C30 -> 32136.42
B32: Equity value (EV + cash - debt) | C32: =C31+$C$9-$C$10 -> 33036.42
B33: Implied price per share (EUR) | C33: =C32/$C$11 -> 30.967773
B34: Terminal reinvestment (% of NOPAT) | C34: =1-P27/P23 -> 0.47489999
B35: PV of terminal value (% of EV) | C35: =C30/C31 -> 0.59407196
B38: Step 1. Change 1 only
B39: Parameter | C39: Value | E39: Line | F39: ="FY"&RIGHT(DCF!O$38,2) -> FY26 | G39: ="FY"&RIGHT(DCF!P$38,2) -> FY27 | H39: ="FY"&RIGHT(DCF!Q$38,2) -> FY28 | I39: ="FY"&RIGHT(DCF!R$38,2) -> FY29 | J39: ="FY"&RIGHT(DCF!S$38,2) -> FY30 | K39: ="FY"&RIGHT(DCF!T$38,2) -> FY31 | L39: ="FY"&RIGHT(DCF!U$38,2) -> FY32 | M39: ="FY"&RIGHT(DCF!V$38,2) -> FY33 | ... O39: ="FY"&RIGHT(DCF!X$38,2) -> FY35 | P39: TV year
B40: Start growth (FY26) | C40: =DCF!$L$11 -> 0.0909 | E40: Revenue growth | F40: =$C$40 -> 0.0909 | G40: =IF($C$44=1,F40-($C$40-$C$43)/$C$12,$C$40) -> 0.0909 | H40: =IF($C$44=1,G40-($C$40-$C$43)/$C$12,$C$40) -> 0.0909 | I40: =IF($C$44=1,H40-($C$40-$C$43)/$C$12,$C$40) -> 0.0909 | J40: =IF($C$44=1,I40-($C$40-$C$43)/$C$12,$C$40) -> 0.0909 | K40: =IF($C$44=1,J40-($C$40-$C$43)/$C$12,$C$40) -> 0.0909 | L40: =IF($C$44=1,K40-($C$40-$C$43)/$C$12,$C$40) -> 0.0909 | M40: =IF($C$44=1,L40-($C$40-$C$43)/$C$12,$C$40) -> 0.0909 | N40: =IF($C$44=1,M40-($C$40-$C$43)/$C$12,$C$40) -> 0.0909 | O40: =IF($C$44=1,N40-($C$40-$C$43)/$C$12,$C$40) -> 0.0909
B41: EBIT margin | C41: =DCF!$L$13 -> 0.1722 | E41: Revenue | F41: =$C$8*(1+F40) -> 15216.419 | G41: =F41*(1+G40) -> 16599.591 | H41: =G41*(1+H40) -> 18108.494 | I41: =H41*(1+I40) -> 19754.556 | J41: =I41*(1+J40) -> 21550.245 | K41: =J41*(1+K40) -> 23509.162 | L41: =K41*(1+L40) -> 25646.145 | M41: =L41*(1+M40) -> 27977.38 | N41: =M41*(1+N40) -> 30520.524 | O41: =N41*(1+O40) -> 33294.839
B42: WACC | C42: =$C$15 -> 0.085833824 | E42: NOPAT = EBIT x (1 - tax) | F42: =F41*$C$41*(1-$C$4) -> 2358.2406 | G42: =G41*$C$41*(1-$C$4) -> 2572.6046 | H42: =H41*$C$41*(1-$C$4) -> 2806.4544 | I42: =I41*$C$41*(1-$C$4) -> 3061.5611 | J42: =J41*$C$41*(1-$C$4) -> 3339.857 | K42: =K41*$C$41*(1-$C$4) -> 3643.45 | L42: =L41*$C$41*(1-$C$4) -> 3974.6396 | M42: =M41*$C$41*(1-$C$4) -> 4335.9343 | ... O42: =O41*$C$41*(1-$C$4) -> 5160.0342 | P42: =O42*(1+$C$43) -> 5237.4347
B43: Terminal growth rate | C43: =DCF!$L$17 -> 0.015 | E43: D&A | F43: =F41*$C$5 -> 1224.9217 | G43: =G41*$C$5 -> 1336.2671 | H43: =H41*$C$5 -> 1457.7338 | I43: =I41*$C$5 -> 1590.2418 | J43: =J41*$C$5 -> 1734.7947 | K43: =K41*$C$5 -> 1892.4876 | L43: =L41*$C$5 -> 2064.5147 | M43: =M41*$C$5 -> 2252.1791 | ... O43: =O41*$C$5 -> 2680.2346
B44: Growth fade (1 = yes, 0 = flat) | C44: 0 | E44: CapEx | F44: =F41*$C$6 -> 2781.5613 | G44: =G41*$C$6 -> 3034.4053 | H44: =H41*$C$6 -> 3310.2327 | I44: =I41*$C$6 -> 3611.1328 | J44: =J41*$C$6 -> 3939.3848 | K44: =K41*$C$6 -> 4297.4749 | L44: =L41*$C$6 -> 4688.1154 | M44: =M41*$C$6 -> 5114.2651 | ... O44: =O41*$C$6 -> 6086.2966
B45: Terminal FCF with g/WACC reinvestment (1 = yes, 0 = old) | C45: 0 | E45: Change in NWC | F45: =F41*$C$7 -> -436.71122 | G45: =G41*$C$7 -> -476.40826 | H45: =H41*$C$7 -> -519.71378 | I45: =I41*$C$7 -> -566.95576 | J45: =J41*$C$7 -> -618.49204 | K45: =K41*$C$7 -> -674.71296 | L45: =L41*$C$7 -> -736.04437 | M45: =M41*$C$7 -> -802.9508 | ... O45: =O41*$C$7 -> -955.56189
...
