Workbook

Sheet DCF
B3: DCF Model - Ryanair
B5: Ticker | D5: RYA.IR | F5: Implied Price Per Share | I5: =S81 -> 31.619801 | K5: Low-end
B6: Date | D6: ='Sources & Checks'!$B$4 -> 46087 | F6: Current Share Price | I6: ='Sources & Checks'!$B$5 -> 26.19 | K6: High-end
B7: Year end | D7: 46112 | F7: Implied Upside/Downside | I7: =I5/I6-1 -> 0.20732344
A9: X | B9: Assumption
B10: Switches | F10: Conservative | J10: Street/Base | N10: Optimistic
B11: Revenue | D11: 2 | F11: Revenue Growth (Norm.) | H11: 0.07 | J11: Revenue Growth (Norm.) | L11: ='Sources & Checks'!$B$19 -> 0.0909 | N11: Revenue Growth (Norm.) | P11: 0.11
B12: EBIT | D12: 2 | F12: Norm. Years: FY17-19, FY24-25 | H12: Fades to TGR | J12: Norm. Years: FY17-19, FY24-25 | L12: Fades to TGR | N12: Norm. Years: FY17-19, FY24-25 | P12: Fades to TGR
B13: WACC | D13: 2 | F13: EBIT Margin (Norm.) | H13: 0.16 | J13: EBIT Margin (Norm.) | L13: ='Sources & Checks'!$B$20 -> 0.1722 | N13: EBIT Margin (Norm.) | P13: 0.185
B14: TGR | D14: 2 | F14: D&A 8.0% | CapEx 18.3% | WC -2.9% | H14: Normalized avg | J14: D&A 8.0% | CapEx 18.3% | WC -2.9% | L14: Normalized avg | N14: D&A 8.0% | CapEx 18.3% | WC -2.9% | P14: Normalized avg
B16: WACC | D16: =CHOOSE(D13,H16,L16,P16) -> 0.085802789 | F16: WACC | H16: 0.092 | J16: WACC | L16: =WACC!F22 -> 0.085802789 | N16: WACC | P16: 0.082
B17: TGR | D17: =CHOOSE(D14,H17,L17,P17) -> 0.015 | F17: TGR | H17: 0.01 | J17: TGR | L17: 0.015 | N17: TGR | P17: 0.02
B18: Fade steps (FY27-FY35) | D18: =COLUMNS(P40:X40) -> 9
A19: X | B19: Income Statement | E19: 2016 | F19: =E19+1 -> 2017 | G19: =F19+1 -> 2018 | H19: =G19+1 -> 2019 | I19: =H19+1 -> 2020 | J19: =I19+1 -> 2021 | K19: =J19+1 -> 2022 | L19: =K19+1 -> 2023 | M19: =L19+1 -> 2024 | ... X19: =W19+1 -> 2035
B20: Revenue | E20: 6535.8 | F20: 6647.8 | G20: 7151 | H20: 7697.4 | I20: 8494.8 | J20: 1635.8 | K20: 4800.9 | L20: 10775.2 | M20: 13443.8 | N20: 13948.5 | O20: =N20*(1+O21) -> 15216.419 | P20: =O20*(1+P21) -> 16471.266 | Q20: =P20*(1+Q21) -> 17690.689 | R20: =Q20*(1+R21) -> 18851.198 | S20: =R20*(1+S21) -> 19928.858 | T20: =T39 -> 20900.058 | U20: =U39 -> 21742.33 | V20: =V39 -> 22435.186 | W20: =W39 -> 22960.917 | X20: =X39 -> 23305.331
B21: % growth | F21: =F20/E20-1 -> 0.017136387 | G21: =G20/F20-1 -> 0.075694215 | H21: =H20/G20-1 -> 0.076408894 | I21: =I20/H20-1 -> 0.10359342 | J21: =J20/I20-1 -> -0.80743514 | K21: =K20/J20-1 -> 1.9348942 | L21: =L20/K20-1 -> 1.2444125 | M21: =M20/L20-1 -> 0.2476613 | N21: =N20/M20-1 -> 0.037541469 | O21: =O40 -> 0.0909 | P21: =P40 -> 0.082466667 | Q21: =Q40 -> 0.074033333 | R21: =R40 -> 0.0656 | S21: =S40 -> 0.057166667 | T21: =T40 -> 0.048733333 | U21: =U40 -> 0.0403 | V21: =V40 -> 0.031866667 | ... X21: =X40 -> 0.015
B22: EBITDA | E22: =E23+E28 -> 1887.4 | F22: =F23+F28 -> 2031.5 | G22: =G23+G28 -> 2228.3 | H22: =H23+H28 -> 1657.3 | I22: =I23+I28 -> 1876.1 | J22: =J23+J28 -> -268.4 | K22: =K23+K28 -> 379.8 | L22: =L23+L28 -> 2365.8 | ... N22: =N23+N28 -> 2772.4 | O22: =O45+O56 -> 3845.189 | P22: =P45+P56 -> 4162.2889 | Q22: =Q45+Q56 -> 4470.437 | R22: =R45+R56 -> 4763.6977 | S22: =S45+S56 -> 5036.0224 | T22: =T45+T56 -> 5281.4446 | U22: =U45+U56 -> 5494.2868 | V22: =V45+V56 -> 5669.3714 | ... X22: =X45+X56 -> 5889.257
B23: EBIT | E23: 1460.1 | F23: 1534 | G23: 1667.3 | H23: 1016.8 | I23: 1127.4 | J23: -839.4 | K23: -339.6 | L23: 1442.6 | M23: 2060.7 | N23: 1558 | O23: =O20*O24 -> 2620.2673 | P23: =P20*P24 -> 2836.352 | Q23: =Q20*Q24 -> 3046.3366 | R23: =R20*R24 -> 3246.1763 | S23: =S20*S24 -> 3431.7494 | T23: =T45 -> 3598.9899 | U23: =U45 -> 3744.0292 | V23: =V45 -> 3863.339 | W23: =W45 -> 3953.8699 | X23: =X45 -> 4013.1779
B24: % of Sales | E24: =E23/E20 -> 0.22340035 | F24: =F23/F20 -> 0.23075303 | G24: =G23/G20 -> 0.2331562 | H24: =H23/H20 -> 0.13209655 | I24: =I23/I20 -> 0.13271649 | J24: =J23/J20 -> -0.51314342 | K24: =K23/K20 -> -0.070736737 | L24: =L23/L20 -> 0.13388151 | ... N24: =N23/N20 -> 0.1116966 | O24: =O46 -> 0.1722 | P24: =P46 -> 0.1722 | Q24: =Q46 -> 0.1722 | R24: =R46 -> 0.1722 | S24: =S46 -> 0.1722 | T24: =T46 -> 0.1722 | U24: =U46 -> 0.1722 | V24: =V46 -> 0.1722 | ... X24: =X46 -> 0.1722
B25: Taxes | E25: 162.8 | F25: 154.4 | G25: 161.1 | H25: 63.1 | I25: 21.6 | J25: -93.6 | K25: -189 | L25: 128.7 | M25: 210.9 | N25: 172.8 | O25: =O23*O26 -> 314.43207 | P25: =P23*P26 -> 340.36224 | Q25: =Q23*Q26 -> 365.56039 | R25: =R23*R26 -> 389.54115 | S25: =S23*S26 -> 411.80992 | T25: =T51 -> 431.87879 | U25: =U51 -> 449.28351 | V25: =V51 -> 463.60068 | W25: =W51 -> 474.46438 | X25: =X51 -> 481.58135
B26: Tax rate | E26: =E25/E23 -> 0.11149921 | F26: =F25/F23 -> 0.10065189 | G26: =G25/G23 -> 0.096623283 | H26: =H25/H23 -> 0.062057435 | I26: =I25/I23 -> 0.019159127 | J26: =J25/J23 -> 0.11150822 | K26: =K25/K23 -> 0.5565371 | L26: =L25/L23 -> 0.089213919 | ... N26: =N25/N23 -> 0.11091142 | O26: =O52 -> 0.12 | P26: =P52 -> 0.12 | Q26: =Q52 -> 0.12 | R26: =R52 -> 0.12 | S26: =S52 -> 0.12 | T26: =T52 -> 0.12 | U26: =U52 -> 0.12 | V26: =V52 -> 0.12 | ... X26: =X52 -> 0.12
A27: X | B27: Cash Flow Items | E27: =E19 -> 2016 | F27: =F19 -> 2017 | G27: =G19 -> 2018 | H27: =H19 -> 2019 | I27: =I19 -> 2020 | J27: =J19 -> 2021 | K27: =K19 -> 2022 | L27: =L19 -> 2023 | ... S27: =S19 -> 2030 | T27: =T38 -> 2031 | U27: =U38 -> 2032 | V27: =V38 -> 2033 | W27: =W38 -> 2034 | X27: =X38 -> 2035
B28: D&A | E28: 427.3 | F28: 497.5 | G28: 561 | H28: 640.5 | I28: 748.7 | J28: 571 | K28: 719.4 | L28: 923.2 | M28: 1059.5 | N28: 1214.4 | O28: =O20*O29 -> 1224.9217 | P28: =P20*P29 -> 1325.9369 | Q28: =Q20*Q29 -> 1424.1004 | R28: =R20*R29 -> 1517.5214 | S28: =S20*S29 -> 1604.2731 | T28: =T56 -> 1682.4546 | U28: =U56 -> 1750.2576 | V28: =V56 -> 1806.0324 | W28: =W56 -> 1848.3538 | X28: =X56 -> 1876.0791
B29: % of Sales | E29: =E28/E20 -> 0.065378378 | F29: =F28/F20 -> 0.074836788 | G29: =G28/G20 -> 0.078450566 | H29: =H28/H20 -> 0.083209915 | I29: =I28/I20 -> 0.088136272 | J29: =J28/J20 -> 0.34906468 | K29: =K28/K20 -> 0.1498469 | L29: =L28/L20 -> 0.085678224 | ... N29: =N28/N20 -> 0.087063125 | O29: =O57 -> 0.0805 | P29: =P57 -> 0.0805 | Q29: =Q57 -> 0.0805 | R29: =R57 -> 0.0805 | S29: =S57 -> 0.0805 | T29: =T57 -> 0.0805 | U29: =U57 -> 0.0805 | V29: =V57 -> 0.0805 | ... X29: =X57 -> 0.0805
B31: CapEx | E31: 1217.7 | F31: 1449.8 | G31: 1470.6 | H31: 1546.7 | I31: 578.8 | J31: 294.7 | K31: 1181.6 | L31: 1914.7 | M31: 2391.9 | N31: 1552.5 | O31: =O20*O32 -> 2781.5613 | P31: =P20*P32 -> 2952.4909 | Q31: =Q20*Q32 -> 3099.7001 | R31: =R20*R32 -> 3215.816 | S31: =S20*S32 -> 3292.8282 | T31: =T59 -> 3321.9838 | U31: =U59 -> 3293.5246 | V31: =V59 -> 3196.1421 | W31: =W59 -> 3015.9106 | X31: =X59 -> 2734.2203
B32: % of Sales | E32: =E31/E20 -> 0.18631231 | F32: =F31/F20 -> 0.21808719 | G32: =G31/G20 -> 0.20564956 | H32: =H31/H20 -> 0.20093798 | I32: =I31/I20 -> 0.068135801 | J32: =J31/J20 -> 0.1801565 | K32: =K31/K20 -> 0.24612052 | L32: =L31/L20 -> 0.17769508 | ... N32: =N31/N20 -> 0.11130229 | O32: =O60 -> 0.1828 | P32: =P60 -> 0.179251 | Q32: =Q60 -> 0.17521648 | R32: =R60 -> 0.17058948 | S32: =S60 -> 0.16522915 | T32: =T60 -> 0.15894616 | U32: =U60 -> 0.15147984 | V32: =V60 -> 0.14246114 | ... X32: =X60 -> 0.11732167
B34: Change in NW | E34: -135.6 | F34: -113.1 | G34: -168.9 | H34: -514.3 | I34: 388.5 | J34: 1703.2 | K34: -1785.9 | L34: -1353.9 | M34: -19 | N34: -480.3 | O34: =O20*O35 -> -436.71122 | P34: =P20*P35 -> -456.32551 | Q34: =Q20*Q35 -> -470.08515 | R34: =R20*R35 -> -476.45213 | S34: =S20*S35 -> -473.71978 | T34: =T62 -> -459.96566 | U34: =U62 -> -432.95956 | V34: =V62 -> -389.99166 | W34: =W62 -> -327.55502 | X34: =X62 -> -240.74929
B35: % of Sales | E35: =E34/E20 -> -0.020747269 | F35: =F34/F20 -> -0.017013147 | G35: =G34/G20 -> -0.023619074 | H35: =H34/H20 -> -0.066814769 | I35: =I34/I20 -> 0.045733861 | J35: =J34/J20 -> 1.0412031 | K35: =K34/K20 -> -0.37199275 | L35: =L34/L20 -> -0.12564964 | ... N35: =N34/N20 -> -0.03443381 | O35: =O63 -> -0.0287 | P35: =P63 -> -0.027704337 | Q35: =Q63 -> -0.026572462 | R35: =R63 -> -0.025274369 | S35: =S63 -> -0.023770543 | T35: =T63 -> -0.022007866 | U35: =U63 -> -0.019913209 | V35: =V63 -> -0.017383037 | ... X35: =X63 -> -0.010330224
B36: % of Change in Sales | F36: =F34/(F20-E20) -> -1.0098214 | G36: =G34/(G20-F20) -> -0.33565183 | H36: =H34/(H20-G20) -> -0.94125183 | I36: =I34/(I20-H20) -> 0.48720843 | J36: =J34/(J20-I20) -> -0.24831608 | K36: =K34/(K20-J20) -> -0.56424758 | L36: =L34/(L20-K20) -> -0.22662069 | M36: =M34/(M20-L20) -> -0.0071198381 | N36: =N34/(N20-M20) -> -0.95165445
A38: X | B38: DCF | E38: =E27 -> 2016 | F38: =E38+1 -> 2017 | G38: =F38+1 -> 2018 | H38: =G38+1 -> 2019 | I38: =H38+1 -> 2020 | J38: =I38+1 -> 2021 | K38: =J38+1 -> 2022 | L38: =K38+1 -> 2023 | M38: =L38+1 -> 2024 | ... X38: =W38+1 -> 2035 | Y38: TV year
B39: Revenue | E39: =E20 -> 6535.8 | F39: =F20 -> 6647.8 | G39: =G20 -> 7151 | H39: =H20 -> 7697.4 | I39: =I20 -> 8494.8 | J39: =J20 -> 1635.8 | K39: =K20 -> 4800.9 | L39: =L20 -> 10775.2 | ... N39: =N20 -> 13948.5 | O39: =N39*(1+O40) -> 15216.419 | P39: =O39*(1+P40) -> 16471.266 | Q39: =P39*(1+Q40) -> 17690.689 | R39: =Q39*(1+R40) -> 18851.198 | S39: =R39*(1+S40) -> 19928.858 | T39: =S39*(1+T40) -> 20900.058 | U39: =T39*(1+U40) -> 21742.33 | V39: =U39*(1+V40) -> 22435.186 | ... X39: =W39*(1+X40) -> 23305.331
B40: % growth | F40: =F39/E39-1 -> 0.017136387 | G40: =G39/F39-1 -> 0.075694215 | H40: =H39/G39-1 -> 0.076408894 | I40: =I39/H39-1 -> 0.10359342 | J40: =J39/I39-1 -> -0.80743514 | K40: =K39/J39-1 -> 1.9348942 | L40: =L39/K39-1 -> 1.2444125 | M40: =M39/L39-1 -> 0.2476613 | N40: =N39/M39-1 -> 0.037541469 | O40: =INDEX(O41:O43,$D$11) -> 0.0909 | P40: =INDEX(P41:P43,$D$11) -> 0.082466667 | Q40: =INDEX(Q41:Q43,$D$11) -> 0.074033333 | R40: =INDEX(R41:R43,$D$11) -> 0.0656 | S40: =INDEX(S41:S43,$D$11) -> 0.057166667 | T40: =INDEX(T41:T43,$D$11) -> 0.048733333 | U40: =INDEX(U41:U43,$D$11) -> 0.0403 | V40: =INDEX(V41:V43,$D$11) -> 0.031866667 | ... X40: =INDEX(X41:X43,$D$11) -> 0.015 | Y40: =$D$17 -> 0.015
B41: Conservative Case | O41: =$H$11 -> 0.07 | P41: =O41-($H$11-$H$17)/$D$18 -> 0.063333333 | Q41: =P41-($H$11-$H$17)/$D$18 -> 0.056666667 | R41: =Q41-($H$11-$H$17)/$D$18 -> 0.05 | S41: =R41-($H$11-$H$17)/$D$18 -> 0.043333333 | T41: =S41-($H$11-$H$17)/$D$18 -> 0.036666667 | U41: =T41-($H$11-$H$17)/$D$18 -> 0.03 | V41: =U41-($H$11-$H$17)/$D$18 -> 0.023333333 | W41: =V41-($H$11-$H$17)/$D$18 -> 0.016666667 | X41: =W41-($H$11-$H$17)/$D$18 -> 0.01
B42: Street Case | O42: =$L$11 -> 0.0909 | P42: =O42-($L$11-$L$17)/$D$18 -> 0.082466667 | Q42: =P42-($L$11-$L$17)/$D$18 -> 0.074033333 | R42: =Q42-($L$11-$L$17)/$D$18 -> 0.0656 | S42: =R42-($L$11-$L$17)/$D$18 -> 0.057166667 | T42: =S42-($L$11-$L$17)/$D$18 -> 0.048733333 | U42: =T42-($L$11-$L$17)/$D$18 -> 0.0403 | V42: =U42-($L$11-$L$17)/$D$18 -> 0.031866667 | W42: =V42-($L$11-$L$17)/$D$18 -> 0.023433333 | X42: =W42-($L$11-$L$17)/$D$18 -> 0.015
B43: Optimistic Case | O43: =$P$11 -> 0.11 | P43: =O43-($P$11-$P$17)/$D$18 -> 0.1 | Q43: =P43-($P$11-$P$17)/$D$18 -> 0.09 | R43: =Q43-($P$11-$P$17)/$D$18 -> 0.08 | S43: =R43-($P$11-$P$17)/$D$18 -> 0.07 | T43: =S43-($P$11-$P$17)/$D$18 -> 0.06 | U43: =T43-($P$11-$P$17)/$D$18 -> 0.05 | V43: =U43-($P$11-$P$17)/$D$18 -> 0.04 | W43: =V43-($P$11-$P$17)/$D$18 -> 0.03 | X43: =W43-($P$11-$P$17)/$D$18 -> 0.02
B45: EBIT | E45: =E23 -> 1460.1 | F45: =F23 -> 1534 | G45: =G23 -> 1667.3 | H45: =H23 -> 1016.8 | I45: =I23 -> 1127.4 | J45: =J23 -> -839.4 | K45: =K23 -> -339.6 | L45: =L23 -> 1442.6 | ... N45: =N23 -> 1558 | O45: =O39*O46 -> 2620.2673 | P45: =P39*P46 -> 2836.352 | Q45: =Q39*Q46 -> 3046.3366 | R45: =R39*R46 -> 3246.1763 | S45: =S39*S46 -> 3431.7494 | T45: =T39*T46 -> 3598.9899 | U45: =U39*U46 -> 3744.0292 | V45: =V39*V46 -> 3863.339 | ... X45: =X39*X46 -> 4013.1779
B46: % of Sales | E46: =E45/E20 -> 0.22340035 | F46: =F45/F20 -> 0.23075303 | G46: =G45/G20 -> 0.2331562 | H46: =H45/H20 -> 0.13209655 | I46: =I45/I20 -> 0.13271649 | J46: =J45/J20 -> -0.51314342 | K46: =K45/K20 -> -0.070736737 | L46: =L45/L20 -> 0.13388151 | ... N46: =N45/N20 -> 0.1116966 | O46: =INDEX(O47:O49,$D$12) -> 0.1722 | P46: =INDEX(P47:P49,$D$12) -> 0.1722 | Q46: =INDEX(Q47:Q49,$D$12) -> 0.1722 | R46: =INDEX(R47:R49,$D$12) -> 0.1722 | S46: =INDEX(S47:S49,$D$12) -> 0.1722 | T46: =INDEX(T47:T49,$D$12) -> 0.1722 | U46: =INDEX(U47:U49,$D$12) -> 0.1722 | V46: =INDEX(V47:V49,$D$12) -> 0.1722 | ... X46: =INDEX(X47:X49,$D$12) -> 0.1722
B47: Conservative Case | O47: =$H$13 -> 0.16 | P47: =$H$13 -> 0.16 | Q47: =$H$13 -> 0.16 | R47: =$H$13 -> 0.16 | S47: =$H$13 -> 0.16 | T47: =$H$13 -> 0.16 | U47: =$H$13 -> 0.16 | V47: =$H$13 -> 0.16 | ... X47: =$H$13 -> 0.16
B48: Street Case | O48: =$L$13 -> 0.1722 | P48: =$L$13 -> 0.1722 | Q48: =$L$13 -> 0.1722 | R48: =$L$13 -> 0.1722 | S48: =$L$13 -> 0.1722 | T48: =$L$13 -> 0.1722 | U48: =$L$13 -> 0.1722 | V48: =$L$13 -> 0.1722 | ... X48: =$L$13 -> 0.1722
B49: Optimistic Case | O49: =$P$13 -> 0.185 | P49: =$P$13 -> 0.185 | Q49: =$P$13 -> 0.185 | R49: =$P$13 -> 0.185 | S49: =$P$13 -> 0.185 | T49: =$P$13 -> 0.185 | U49: =$P$13 -> 0.185 | V49: =$P$13 -> 0.185 | ... X49: =$P$13 -> 0.185
...

Sheet Notes
B1: Model notes
B3: Method
B4: Cost of equity | C4: WACC!F14, F10 | D4: Blume adjusted beta = 1/3 x 1 + 2/3 x raw beta, used in the cost of equity.
B5: Revenue growth | C5: DCF!P41:X43, D18 | D5: FY26 growth is the scenario rate. From FY27 growth falls by (start growth - TGR) / 9 a year, so FY35 growth equals the terminal growth rate.
B6: Reinvestment | C6: DCF!P60:X65 | D6: Reinvestment rate = growth / RONIC. FY26 is implied by the CapEx, D&A and working capital assumptions. From FY27 RONIC fades in equal steps to WACC in FY35. CapEx and working capital follow it.
B7: Terminal value | C7: DCF!Y54:Y66, X73 | D7: Terminal FCF = NOPAT FY35 x (1+g) x (1 - g/WACC), TV = terminal FCF / (WACC - g). RONIC = WACC, so the terminal year continues the FY35 reinvestment rate.
B8: Tax rate | C8: Sources & Checks!B14 | D8: Effective tax rate of 12%, as reported in the Q3 FY26 results (note 4).
B9: FY26 cash flow | C9: DCF!O67 | D9: Only the 25 days between the valuation date and the FY26 year end are counted.
B10: Equity bridge | C10: Sources & Checks!B24, DCF!S77 | D10: Lease liabilities of 111.2 (Q3 FY26 balance sheet) are deducted together with gross debt.

Sheet Valuation
B2: Comps
N4: Financial Data | T4: Multiples | Y4: Multiples (EBIT basis)
H5: Price | J5: Market Cap | L5: EV | N5: Growth 24 | O5: Growth 25 | Q5: EBIT Margin 24 | R5: EBIT Margin 25 | T5: EV/EBITDA 24 | U5: EV/EBITDA 25 | W5: EV/Sales 24 | X5: EV/Sales 25 | Y5: EV/EBIT 24 | Z5: EV/EBIT 25
B6: Ticker | D6: Name | H6: (Local CCY) | J6: (Local CCY M) | L6: (Local CCY M) | N6: (%) | O6: (%) | Q6: (%) | R6: (%) | T6: (x) | U6: (x) | V6: (x) | W6: (x) | X6: (x) | Y6: (x) | Z6: (x)
H7: EUR / GBP | J7: EUR M / GBP M | L7: EUR M / GBP M
B8: RYA.IR | D8: Ryanair Holdings plc | H8: ='Sources & Checks'!$B$5 -> 26.19 | J8: ='Sources & Checks'!$B$8*H8 -> 27499.5 | L8: =J8-'Sources & Checks'!$B$6+'Sources & Checks'!$B$7+'Sources & Checks'!$B$24 -> 26710.7 | N8: =DCF!M21 -> 0.2476613 | O8: =DCF!N21 -> 0.037541469 | Q8: =DCF!M24 -> 0.15328255 | R8: =DCF!N24 -> 0.1116966 | T8: =L8/DCF!M22 -> 8.560573 | U8: =L8/DCF!N22 -> 9.6345044 | W8: =L8/DCF!M20 -> 1.9868415 | X8: =L8/DCF!N20 -> 1.9149514 | Y8: =L8/DCF!M23 -> 12.961955 | Z8: =L8/DCF!N23 -> 17.144223
B10: EZJ.L | D10: easyJet plc | H10: 4.089 | J10: 3287.49 | L10: 2450 | N10: 0.1393 | O10: 0.0856 | Q10: 0.064131486 | R10: 0.069562636 | T10: 1.7922458 | U10: 1.6943292 | W10: 0.26318616 | X10: 0.24243024 | Y10: 4.1039 | Z10: 3.485
B11: WIZZ.L | D11: Wizz Air Holdings plc | H11: 9.275 | J11: 1166.6 | L11: 5950.1 | N11: 0.3 | O11: 0.0454 | Q11: 0.086370809 | R11: 0.031603774 | T11: 4.9866745 | U11: 5.245614 | W11: 1.1735897 | X11: 1.1226604 | Y11: 13.5878 | Z11: 35.5227
B12: IAG.MC | D12: International Airlines Group | H12: 4.464 | J12: 19080 | L12: 25060 | N12: 0.089871999 | O12: 0.034672897 | Q12: 0.13841121 | R12: 0.15126607 | T12: 3.6815043 | U12: 3.2978023 | W12: 0.78068536 | X12: 0.75452383 | Y12: 5.6403 | Z12: 4.9881
B13: LHA.DE | D13: Deutsche Lufthansa AG | H13: 8.12 | J13: 9740 | L13: 17780 | N13: 0.060352125 | O13: 0.053644129 | Q13: 0.043772119 | R13: 0.049498699 | T13: 4.4650929 | U13: 4.1071841 | W13: 0.47311141 | X13: 0.44902392 | Y13: 10.8085 | Z13: 9.0714
B14: AF.PA | D14: Air France-KLM | H14: 10.09 | J14: 2650 | L14: 3020 | N14: 0.047969619 | O14: 0.049206904 | Q14: 0.051 | R14: 0.061 | T14: 0.71159284 | U14: 0.59707394 | W14: 0.095997966 | X14: 0.091495743 | Y14: 1.8822 | Z14: 1.5
B20: PEER AVG (EX-RYA) | N20: =IF(COUNT(N10:N17)=0,"",AVERAGE(N10:N17)) -> 0.12749875 | O20: =IF(COUNT(O10:O17)=0,"",AVERAGE(O10:O17)) -> 0.053704786 | P20: =IF(COUNT(P8:P17)=0,"",AVERAGE(P8:P17)) | Q20: =IF(COUNT(Q10:Q17)=0,"",AVERAGE(Q10:Q17)) -> 0.076737126 | R20: =IF(COUNT(R10:R17)=0,"",AVERAGE(R10:R17)) -> 0.072586236 | S20: =IF(COUNT(S8:S17)=0,"",AVERAGE(S8:S17)) | T20: =IF(COUNT(T10:T17)=0,"",AVERAGE(T10:T17)) -> 3.1274221 | U20: =IF(COUNT(U10:U17)=0,"",AVERAGE(U10:U17)) -> 2.9884007 | V20: =IF(COUNT(V8:V17)=0,"",AVERAGE(V8:V17)) | W20: =IF(COUNT(W10:W17)=0,"",AVERAGE(W10:W17)) -> 0.55731413 | X20: =IF(COUNT(X10:X17)=0,"",AVERAGE(X10:X17)) -> 0.53202682 | Y20: =IF(COUNT(Y10:Y17)=0,"",AVERAGE(Y10:Y17)) -> 7.20454 | Z20: =IF(COUNT(Z10:Z17)=0,"",AVERAGE(Z10:Z17)) -> 10.91344
B21: PEER MEDIAN (EX-RYA) | N21: =IF(COUNT(N10:N17)=0,"",MEDIAN(N10:N17)) -> 0.089871999 | O21: =IF(COUNT(O10:O17)=0,"",MEDIAN(O10:O17)) -> 0.049206904 | P21: =IF(COUNT(P8:P17)=0,"",MEDIAN(P8:P17)) | Q21: =IF(COUNT(Q10:Q17)=0,"",MEDIAN(Q10:Q17)) -> 0.064131486 | R21: =IF(COUNT(R10:R17)=0,"",MEDIAN(R10:R17)) -> 0.061 | S21: =IF(COUNT(S8:S17)=0,"",MEDIAN(S8:S17)) | T21: =IF(COUNT(T10:T17)=0,"",MEDIAN(T10:T17)) -> 3.6815043 | U21: =IF(COUNT(U10:U17)=0,"",MEDIAN(U10:U17)) -> 3.2978023 | V21: =IF(COUNT(V8:V17)=0,"",MEDIAN(V8:V17)) | W21: =IF(COUNT(W10:W17)=0,"",MEDIAN(W10:W17)) -> 0.47311141 | X21: =IF(COUNT(X10:X17)=0,"",MEDIAN(X10:X17)) -> 0.44902392 | Y21: =IF(COUNT(Y10:Y17)=0,"",MEDIAN(Y10:Y17)) -> 5.6403 | Z21: =IF(COUNT(Z10:Z17)=0,"",MEDIAN(Z10:Z17)) -> 4.9881
B24: Implied Valuation from Peer Medians (Ryanair)
B25: Metric | C25: Peer Median Multiple (FY25) | D25: Ryanair Metric (FY25, EUR M) | E25: Implied EV (EUR M) | F25: (+) Cash | G25: (-) Debt | H25: Implied Equity (EUR M) | I25: Implied Price (€) | J25: vs. Mkt €26.19
B26: EV/EBITDA (FY25) | C26: =U21 -> 3.2978023 | D26: =DCF!N22 -> 2772.4 | E26: =C26*D26 -> 9142.8272 | F26: ='Sources & Checks'!$B$6 -> 2400 | G26: ='Sources & Checks'!$B$7+'Sources & Checks'!$B$24 -> 1611.2 | H26: =E26+F26-G26 -> 9931.6272 | I26: =H26/'Sources & Checks'!$B$9 -> 9.3097368 | J26: =I26/'Sources & Checks'!$B$5-1 -> -0.64453086
B27: EV/Sales (FY25) | C27: =X21 -> 0.44902392 | D27: =DCF!N20 -> 13948.5 | E27: =C27*D27 -> 6263.2101 | F27: ='Sources & Checks'!$B$6 -> 2400 | G27: ='Sources & Checks'!$B$7+'Sources & Checks'!$B$24 -> 1611.2 | H27: =E27+F27-G27 -> 7052.0101 | I27: =H27/'Sources & Checks'!$B$9 -> 6.6104332 | J27: =I27/'Sources & Checks'!$B$5-1 -> -0.74759705
B28: EV/EBIT (FY25) | C28: =Z21 -> 4.9881 | D28: =DCF!N23 -> 1558 | E28: =C28*D28 -> 7771.4598 | F28: ='Sources & Checks'!$B$6 -> 2400 | G28: ='Sources & Checks'!$B$7+'Sources & Checks'!$B$24 -> 1611.2 | H28: =E28+F28-G28 -> 8560.2598 | I28: =H28/'Sources & Checks'!$B$9 -> 8.0242405 | J28: =I28/'Sources & Checks'!$B$5-1 -> -0.69361434
B30: Note: Peer medians exclude Ryanair (EX-RYA). Implied EV = Multiple × Ryanair metric. Net Debt Bridge: (+) Cash €2,400M, (−) Debt €1,500M and leases €111M. Shares: 1,066.8M diluted. Large discount vs DCF reflects Ryanair's structurally superior margins vs legacy carriers — direct comps multiples understate intrinsic value.

Sheet WACC
B2: WACC
B4: WACC = % of equity x cost of equity + % of debt x cost of debt x (1- Tax Rate)
B5: Cost of equity = Risk Free rate + Adjusted Beta x Market Risk Premium
A7: X | B7: WACC
B8: Market Cap | F8: ='Sources & Checks'!$B$8*'Sources & Checks'!$B$5 -> 27499.5
B9: % of Equity | F9: =F8/(F8+F15) -> 0.94827497
B10: Cost of Equity | F10: =F11+F14*F13 -> 0.089043
B11: Risk Free Rate | F11: ='Sources & Checks'!$B$10 -> 0.028643
B12: Beta (raw) | F12: ='Sources & Checks'!$B$11 -> 1.01
B13: Market Risk Premium | F13: ='Sources & Checks'!$B$12 -> 0.06
B14: Adjusted Beta (Blume: 1/3 x 1.0 + 2/3 x raw beta) | F14: =1/3*1+2/3*F12 -> 1.0066667
A15: X | B15: Debt | F15: ='Sources & Checks'!$B$7 -> 1500
B16: % of Debt | F16: =F15/(F15+F8) -> 0.05172503
B17: Cost of Debt | F17: ='Sources & Checks'!$B$13 -> 0.03
B18: Tax Rate | F18: ='Sources & Checks'!$B$14 -> 0.12
A20: X | B20: Total | F20: =F15+F8 -> 28999.5
A22: X | B22: WACC | F22: =F9*F10+(F16*F17*(1-F18)) -> 0.085802789

Sheet Sources & Checks
A1: Verified Inputs & Sources
A3: Metric | B3: Value | C3: Units | D3: Source / Note
A4: Valuation date | B4: 46087 | C4: date | D4: Aligned to market price date used in the model.
A5: Current share price | B5: 26.19 | C5: EUR/share | D5: Euronext Dublin last traded price on 06/03/2026.
A6: Gross cash | B6: 2400 | C6: EUR m | D6: Ryanair Q3 FY26 results: gross cash at 31 Dec 2025.
A7: Gross debt | B7: 1500 | C7: EUR m | D7: Ryanair Q3 FY26 results: gross debt at 31 Dec 2025.
A8: Basic shares outstanding | B8: 1050 | C8: m shares | D8: Balance at 31 Dec 2025; used for market cap and EV bridge.
A9: Diluted shares | B9: 1066.8 | C9: m shares | D9: 9M FY26 diluted weighted average shares; used for per-share DCF.
A10: Risk-free rate | B10: 0.028643 | C10: % | D10: Germany 10Y government bond yield on 06/03/2026.
A11: Beta | B11: 1.01 | C11: x | D11: Analyst assumption.
A12: Market risk premium | B12: 0.06 | C12: % | D12: Analyst assumption.
A13: Pre-tax cost of debt | B13: 0.03 | C13: % | D13: Analyst assumption.
A14: Tax rate | B14: 0.12 | C14: % | D14: Q3 FY26 results, note 4: effective tax rate approx. 12% for the nine months to 31 Dec 2025 (prior year approx. 12%).
A16: Control note | B16: Market cap uses basic shares; DCF per-share output uses diluted shares.
A18: DCF Forecast Methodology | B18: Normalized Historical Average | C18: - | D18: All forecast drivers (revenue growth, EBIT margin, D&A, CapEx, ΔWC) use flat normalized avg. Normal years: FY2017-2019 + FY2024-2025. Excluded: FY2020-2023 (Covid disruption + rebound distortion). Revenue growth starts at the normalised rate in FY26 and fades in equal steps to the terminal growth rate by FY35. From FY27 the reinvestment rate equals growth / RONIC, with RONIC fading from its FY26 implied level to WACC.
A19: Normalized Revenue Growth | B19: 0.0909 | C19: % | D19: Avg of FY17(1.7%), FY18(7.6%), FY19(7.6%), FY24(24.8%), FY25(3.8%) excl. Covid years
A20: Normalized EBIT Margin | B20: 0.1722 | C20: % | D20: Avg of FY17(23.1%), FY18(23.3%), FY19(13.2%), FY24(15.3%), FY25(11.2%) excl. Covid years
A21: Normalized D&A % | B21: 0.0805 | C21: % | D21: Avg of FY17-FY19 + FY24-FY25 D&A as % of Revenue
A22: Normalized CapEx % | B22: 0.1828 | C22: % | D22: Avg of FY17-FY19 + FY24-FY25 CapEx as % of Revenue
A23: Normalized ΔWC % | B23: -0.0287 | C23: % | D23: Avg of FY17-FY19 + FY24-FY25 change in net working capital as % of Revenue (negative = cash source, typical for airlines)
A24: Lease liabilities | B24: 111.2 | C24: EUR m | D24: Q3 FY26 results balance sheet at 31 Dec 2025: current 35.3 + non-current 75.9. Added to gross debt in the equity bridge.
A25: ⚠ Data Note | B25: FY2016 historical revenue (€6,535.8M) should be verified against Ryanair's FY2016 Annual Report (year ended 31 March 2016). Some databases report FY2016 total revenues as ~€5,654M (ex-ancillary supplements). If restated, the normalized growth average would adjust from 9.09% to approx. 9.5%.

Sheet Ratios
B3: Income Statement Data (€ million) | C3: FY23 | D3: FY24 | E3: FY25
B4: Total Revenue1 | C4: 10775 | D4: 13444 | E4: 13949
B5: Total Operating Costs1 | C5: 9332 | D5: 11383 | E5: 12391
B6: Profit Before Tax1 | C6: 1443 | D6: 2128 | E6: 1785
B7: Profit After Tax (Net Income)1 | C7: 1314 | D7: 1917 | E7: 1612
B10: Balance Sheet Data (€ million) | C10: FY23 | D10: FY24 | E10: FY25
B11: Total Assets1 | C11: 16406 | D11: 17176 | E11: 17507
B12: Shareholder Equity1 | C12: 5643 | D12: 7614 | E12: 7037
B13: Gross Cash1 | C13: 4675 | D13: 4120 | E13: 3987
B16: Debt | C16: FY23 | D16: FY24 | E16: FY25
B17: Current Liabilities1 | C17: 7422 | D17: 6401 | E17: 8153
B18: Non-Current Liabilities1 | C18: 3341 | D18: 3161 | E18: 2317
B19: Total Liabilities | C19: =C17+C18 -> 10763 | D19: =D17+D18 -> 9562 | E19: =E17+E18 -> 10470
B22: Ratio | C22: FY23 | D22: FY24 | E22: FY25
B23: Revenue Growth | C23: =(C4-4800.9)/4800.9 -> 1.2443708 | D23: =(D4-C4)/C4 -> 0.24770302 | E23: =(E4-D4)/D4 -> 0.037563225
B24: Net Income Growth | C24: n.m | D24: =(D7-C7)/C7 -> 0.45890411 | E24: =(E7-D7)/D7 -> -0.15910276
B25: Net Profit Margin | C25: =C7/C4 -> 0.12194896 | D25: =D7/D4 -> 0.14259149 | E25: =E7/E4 -> 0.11556384
B26: Operating Margin | C26: =(C4-C5)/C4 -> 0.13392111 | D26: =(D4-D5)/D4 -> 0.15330259 | E26: =(E4-E5)/E4 -> 0.11169259
B27: Cost-to-Revenue | C27: =C5/C4 -> 0.86607889 | D27: =D5/D4 -> 0.84669741 | E27: =E5/E4 -> 0.88830741
B28: ROA | C28: =C7/C11 -> 0.080092649 | D28: =D7/D11 -> 0.11160922 | E28: =E7/E11 -> 0.092077455
B29: ROE | C29: =C7/C12 -> 0.23285486 | D29: =D7/D12 -> 0.25177305 | E29: =E7/E12 -> 0.22907489
B30: Liabilities Ratio | C30: =C19/C11 -> 0.65604047 | D30: =D19/D11 -> 0.55670703 | E30: =E19/E11 -> 0.5980465
B31: Equity Ratio | C31: =C12/C11 -> 0.34395953 | D31: =D12/D11 -> 0.44329297 | E31: =E12/E11 -> 0.4019535
B33: 1 Ryanair Holdings plc. (2025). Ryanair 2025 annual report. Retrieved 6 March 2026
B35: Note: Revenue Growth (FY23) - Calculated using FY22 revenue of €4,800.9m and FY23 revenue of €10,775m, resulting in growth of 124.40%. FY22 is used only as a base year.
B36: Note: Net Income Growth (FY23) - FY22 net income was a loss of €240.8m, while FY23 net income was €1,313.8m. Because the base year is negative, the growth rate is not meaningful and reflects a turnaround from loss to profit.

Sheet Calc
B1: Calc
B3: Inputs
B4: Tax rate | C4: ='Sources & Checks'!$B$14 -> 0.12
B5: D&A (% of sales) | C5: ='Sources & Checks'!$B$21 -> 0.0805
B6: CapEx (% of sales, FY26 level) | C6: ='Sources & Checks'!$B$22 -> 0.1828
B7: Change in NWC (% of sales, FY26 level, negative = cash source) | C7: ='Sources & Checks'!$B$23 -> -0.0287
B8: Revenue FY25 (base year, EUR m) | C8: =DCF!$N$20 -> 13948.5
B9: Cash (EUR m) | C9: ='Sources & Checks'!$B$6 -> 2400
B10: Debt and leases (EUR m) | C10: ='Sources & Checks'!$B$7+'Sources & Checks'!$B$24 -> 1611.2
B11: Diluted shares (m) | C11: ='Sources & Checks'!$B$9 -> 1066.8
B12: Fade steps (FY27-FY35) | C12: =DCF!$D$18 -> 9
B14: Scenarios
B15: Conservative
B16: Parameter | C16: Value | E16: Line | F16: ="FY"&RIGHT(DCF!O$38,2) -> FY26 | G16: ="FY"&RIGHT(DCF!P$38,2) -> FY27 | H16: ="FY"&RIGHT(DCF!Q$38,2) -> FY28 | I16: ="FY"&RIGHT(DCF!R$38,2) -> FY29 | J16: ="FY"&RIGHT(DCF!S$38,2) -> FY30 | K16: ="FY"&RIGHT(DCF!T$38,2) -> FY31 | L16: ="FY"&RIGHT(DCF!U$38,2) -> FY32 | M16: ="FY"&RIGHT(DCF!V$38,2) -> FY33 | ... O16: ="FY"&RIGHT(DCF!X$38,2) -> FY35 | P16: TV year
B17: Start growth (FY26) | C17: =DCF!$H$11 -> 0.07 | E17: Revenue growth | F17: =$C$17 -> 0.07 | G17: =F17-($C$17-$C$20)/$C$12 -> 0.063333333 | H17: =G17-($C$17-$C$20)/$C$12 -> 0.056666667 | I17: =H17-($C$17-$C$20)/$C$12 -> 0.05 | J17: =I17-($C$17-$C$20)/$C$12 -> 0.043333333 | K17: =J17-($C$17-$C$20)/$C$12 -> 0.036666667 | L17: =K17-($C$17-$C$20)/$C$12 -> 0.03 | M17: =L17-($C$17-$C$20)/$C$12 -> 0.023333333 | N17: =M17-($C$17-$C$20)/$C$12 -> 0.016666667 | O17: =N17-($C$17-$C$20)/$C$12 -> 0.01
B18: EBIT margin | C18: =DCF!$H$13 -> 0.16 | E18: Revenue | F18: =$C$8*(1+F17) -> 14924.895 | G18: =F18*(1+G17) -> 15870.138 | H18: =G18*(1+H17) -> 16769.446 | I18: =H18*(1+I17) -> 17607.918 | J18: =I18*(1+J17) -> 18370.928 | K18: =J18*(1+K17) -> 19044.529 | L18: =K18*(1+L17) -> 19615.865 | M18: =L18*(1+M17) -> 20073.568 | N18: =M18*(1+N17) -> 20408.128 | O18: =N18*(1+O17) -> 20612.209
B19: WACC | C19: =DCF!$H$16 -> 0.092 | E19: NOPAT = EBIT x (1 - tax) | F19: =F18*$C$18*(1-$C$4) -> 2101.4252 | G19: =G18*$C$18*(1-$C$4) -> 2234.5155 | H19: =H18*$C$18*(1-$C$4) -> 2361.138 | I19: =I18*$C$18*(1-$C$4) -> 2479.1949 | J19: =J18*$C$18*(1-$C$4) -> 2586.6267 | K19: =K18*$C$18*(1-$C$4) -> 2681.4697 | L19: =L18*$C$18*(1-$C$4) -> 2761.9138 | M19: =M18*$C$18*(1-$C$4) -> 2826.3584 | ... O19: =O18*$C$18*(1-$C$4) -> 2902.199 | P19: =O19*(1+$C$20) -> 2931.221
B20: Terminal growth rate | C20: =DCF!$H$17 -> 0.01 | E20: RONIC | F20: =$C$17/(($C$6-$C$5+$C$7)/($C$18*(1-$C$4))) -> 0.13391304 | G20: =F20-($F20-$C$19)/$C$12 -> 0.12925604 | H20: =G20-($F20-$C$19)/$C$12 -> 0.12459903 | I20: =H20-($F20-$C$19)/$C$12 -> 0.11994203 | J20: =I20-($F20-$C$19)/$C$12 -> 0.11528502 | K20: =J20-($F20-$C$19)/$C$12 -> 0.11062802 | L20: =K20-($F20-$C$19)/$C$12 -> 0.10597101 | M20: =L20-($F20-$C$19)/$C$12 -> 0.10131401 | N20: =M20-($F20-$C$19)/$C$12 -> 0.096657005 | O20: =N20-($F20-$C$19)/$C$12 -> 0.092 | P20: =$C$19 -> 0.092
E21: Reinvestment rate (% of NOPAT) | F21: =F17/F20 -> 0.52272727 | G21: =G17/G20 -> 0.48998356 | H21: =H17/H20 -> 0.45479218 | I21: =I17/I20 -> 0.41686805 | J21: =J17/J20 -> 0.37587999 | K21: =K17/K20 -> 0.33144105 | L21: =L17/L20 -> 0.28309628 | M21: =M17/M20 -> 0.23030708 | ... O21: =O17/O20 -> 0.10869565 | P21: =$C$20/P20 -> 0.10869565
E22: Net reinvestment (CapEx - D&A + change in NWC) | F22: =F19*F21 -> 1098.4723 | G22: =G19*G21 -> 1094.8758 | H22: =H19*H21 -> 1073.8271 | I22: =I19*I21 -> 1033.4972 | J22: =J19*J21 -> 972.26121 | K22: =K19*K21 -> 888.74912 | L22: =L19*L21 -> 781.88752 | M22: =M19*M21 -> 650.93035 | ... O22: =O19*O21 -> 315.45642
E23: Unlevered FCF | F23: =F19-F22 -> 1002.9529 | G23: =G19-G22 -> 1139.6396 | H23: =H19-H22 -> 1287.3109 | I23: =I19-I22 -> 1445.6978 | J23: =J19-J22 -> 1614.3655 | K23: =K19-K22 -> 1792.7206 | L23: =L19-L22 -> 1980.0263 | M23: =M19-M22 -> 2175.4281 | ... O23: =O19-O22 -> 2586.7426 | P23: =P19*(1-P21) -> 2612.6101
B24: Sum of PV of FCF FY26 to FY35 | C24: =SUM(F25:O25) -> 10677.235 | E24: Discount period (years) | F24: =DCF!O$71 -> 0.034722222 | G24: =DCF!P$71 -> 0.56944444 | H24: =DCF!Q$71 -> 1.5694444 | I24: =DCF!R$71 -> 2.5694444 | J24: =DCF!S$71 -> 3.5694444 | K24: =DCF!T$71 -> 4.5694444 | L24: =DCF!U$71 -> 5.5694444 | M24: =DCF!V$71 -> 6.5694444 | ... O24: =DCF!X$71 -> 8.5694444
B25: Terminal value | C25: =P23/($C$19-$C$20) -> 31861.098 | E25: PV of FCF | F25: =F23*DCF!$O$70/(1+$C$19)^F24 -> 69.436991 | G25: =G23/(1+$C$19)^G24 -> 1083.9316 | H25: =H23/(1+$C$19)^H24 -> 1121.2311 | I25: =I23/(1+$C$19)^I24 -> 1153.0989 | J25: =J23/(1+$C$19)^J24 -> 1179.1479 | K25: =K23/(1+$C$19)^K24 -> 1199.1027 | L25: =L23/(1+$C$19)^L24 -> 1212.8081 | M25: =M23/(1+$C$19)^M24 -> 1220.2343 | N25: =N23/(1+$C$19)^N24 -> 1221.4787 | O25: =O23/(1+$C$19)^O24 -> 1216.7643
B26: PV of terminal value | C26: =C25/(1+$C$19)^O24 -> 14986.974
B27: Enterprise value | C27: =C24+C26 -> 25664.209
B28: Equity value (EV + cash - debt and leases) | C28: =C27+$C$9-$C$10 -> 26453.009
B29: Implied price per share (EUR) | C29: =C28/$C$11 -> 24.796596
B30: Terminal reinvestment (% of NOPAT) | C30: =1-P23/P19 -> 0.10869565
B31: PV of terminal value (% of EV) | C31: =C26/C27 -> 0.58396401
B34: Base / Street
B35: Parameter | C35: Value | E35: Line | F35: ="FY"&RIGHT(DCF!O$38,2) -> FY26 | G35: ="FY"&RIGHT(DCF!P$38,2) -> FY27 | H35: ="FY"&RIGHT(DCF!Q$38,2) -> FY28 | I35: ="FY"&RIGHT(DCF!R$38,2) -> FY29 | J35: ="FY"&RIGHT(DCF!S$38,2) -> FY30 | K35: ="FY"&RIGHT(DCF!T$38,2) -> FY31 | L35: ="FY"&RIGHT(DCF!U$38,2) -> FY32 | M35: ="FY"&RIGHT(DCF!V$38,2) -> FY33 | ... O35: ="FY"&RIGHT(DCF!X$38,2) -> FY35 | P35: TV year
B36: Start growth (FY26) | C36: =DCF!$L$11 -> 0.0909 | E36: Revenue growth | F36: =$C$36 -> 0.0909 | G36: =F36-($C$36-$C$39)/$C$12 -> 0.082466667 | H36: =G36-($C$36-$C$39)/$C$12 -> 0.074033333 | I36: =H36-($C$36-$C$39)/$C$12 -> 0.0656 | J36: =I36-($C$36-$C$39)/$C$12 -> 0.057166667 | K36: =J36-($C$36-$C$39)/$C$12 -> 0.048733333 | L36: =K36-($C$36-$C$39)/$C$12 -> 0.0403 | M36: =L36-($C$36-$C$39)/$C$12 -> 0.031866667 | N36: =M36-($C$36-$C$39)/$C$12 -> 0.023433333 | O36: =N36-($C$36-$C$39)/$C$12 -> 0.015
B37: EBIT margin | C37: =DCF!$L$13 -> 0.1722 | E37: Revenue | F37: =$C$8*(1+F36) -> 15216.419 | G37: =F37*(1+G36) -> 16471.266 | H37: =G37*(1+H36) -> 17690.689 | I37: =H37*(1+I36) -> 18851.198 | J37: =I37*(1+J36) -> 19928.858 | K37: =J37*(1+K36) -> 20900.058 | L37: =K37*(1+L36) -> 21742.33 | M37: =L37*(1+M36) -> 22435.186 | N37: =M37*(1+N36) -> 22960.917 | O37: =N37*(1+O36) -> 23305.331
B38: WACC | C38: =DCF!$L$16 -> 0.085802789 | E38: NOPAT = EBIT x (1 - tax) | F38: =F37*$C$37*(1-$C$4) -> 2305.8352 | G38: =G37*$C$37*(1-$C$4) -> 2495.9898 | H38: =H37*$C$37*(1-$C$4) -> 2680.7762 | I38: =I37*$C$37*(1-$C$4) -> 2856.6351 | J38: =J37*$C$37*(1-$C$4) -> 3019.9394 | K38: =K37*$C$37*(1-$C$4) -> 3167.1111 | L38: =L37*$C$37*(1-$C$4) -> 3294.7457 | M38: =M37*$C$37*(1-$C$4) -> 3399.7383 | ... O38: =O37*$C$37*(1-$C$4) -> 3531.5966 | P38: =O38*(1+$C$39) -> 3584.5705
B39: Terminal growth rate | C39: =DCF!$L$17 -> 0.015 | E39: RONIC | F39: =$C$36/(($C$6-$C$5+$C$7)/($C$37*(1-$C$4))) -> 0.1871552 | G39: =F39-($F39-$C$38)/$C$12 -> 0.17589382 | H39: =G39-($F39-$C$38)/$C$12 -> 0.16463244 | I39: =H39-($F39-$C$38)/$C$12 -> 0.15337106 | J39: =I39-($F39-$C$38)/$C$12 -> 0.14210968 | K39: =J39-($F39-$C$38)/$C$12 -> 0.1308483 | L39: =K39-($F39-$C$38)/$C$12 -> 0.11958692 | M39: =L39-($F39-$C$38)/$C$12 -> 0.10832555 | N39: =M39-($F39-$C$38)/$C$12 -> 0.097064167 | O39: =N39-($F39-$C$38)/$C$12 -> 0.085802789 | P39: =$C$38 -> 0.085802789
E40: Reinvestment rate (% of NOPAT) | F40: =F36/F39 -> 0.48569317 | G40: =G36/G39 -> 0.46884346 | H40: =H36/H39 -> 0.44968862 | I40: =I36/I39 -> 0.42772085 | J40: =J36/J39 -> 0.40227144 | K40: =K36/K39 -> 0.37244146 | L40: =L36/L39 -> 0.33699336 | M40: =M36/M39 -> 0.29417499 | ... O40: =O36/O39 -> 0.17481949 | P40: =$C$39/P39 -> 0.17481949
E41: Net reinvestment (CapEx - D&A + change in NWC) | F41: =F38*F40 -> 1119.9284 | G41: =G38*G40 -> 1170.2285 | H41: =H38*H40 -> 1205.5145 | I41: =I38*I40 -> 1221.8424 | J41: =J38*J40 -> 1214.8354 | K41: =K38*K40 -> 1179.5635 | L41: =L38*L40 -> 1110.3074 | M41: =M38*M40 -> 1000.118 | ... O41: =O38*O40 -> 617.39192
E42: Unlevered FCF | F42: =F38-F41 -> 1185.9068 | G42: =G38-G41 -> 1325.7613 | H42: =H38-H41 -> 1475.2617 | I42: =I38-I41 -> 1634.7927 | J42: =J38-J41 -> 1805.104 | K42: =K38-K41 -> 1987.5476 | L42: =L38-L41 -> 2184.4383 | M42: =M38-M41 -> 2399.6203 | ... O42: =O38-O41 -> 2914.2047 | P42: =P38*(1-P40) -> 2957.9177
B43: Sum of PV of FCF FY26 to FY35 | C43: =SUM(F44:O44) -> 12309.845 | E43: Discount period (years) | F43: =DCF!O$71 -> 0.034722222 | G43: =DCF!P$71 -> 0.56944444 | H43: =DCF!Q$71 -> 1.5694444 | I43: =DCF!R$71 -> 2.5694444 | J43: =DCF!S$71 -> 3.5694444 | K43: =DCF!T$71 -> 4.5694444 | L43: =DCF!U$71 -> 5.5694444 | M43: =DCF!V$71 -> 6.5694444 | ... O43: =DCF!X$71 -> 8.5694444
B44: Terminal value | C44: =P42/($C$38-$C$39) -> 41776.853 | E44: PV of FCF | F44: =F42*DCF!$O$70/(1+$C$38)^F43 -> 82.119579 | G44: =G42/(1+$C$38)^G43 -> 1265.0484 | H44: =H42/(1+$C$38)^H43 -> 1296.4624 | I44: =I42/(1+$C$38)^I43 -> 1323.1303 | J44: =J42/(1+$C$38)^J43 -> 1345.5232 | K44: =K42/(1+$C$38)^K43 -> 1364.4435 | L44: =L42/(1+$C$38)^L43 -> 1381.1054 | M44: =M42/(1+$C$38)^M43 -> 1397.2645 | N44: =N42/(1+$C$38)^N43 -> 1415.4384 | O44: =O42/(1+$C$38)^O43 -> 1439.3097
...
